Workbook
Name anaf: info!$B$1:$F$12
Name PERMYA: #REF!
Name PERMYA: 'data (2)'!$B$5:$L$26

Sheet כללי
G1: ענפים מרכזים | H1: 221 | I1: 421 | J1: 200 | K1: 400 | L1: 100 | M1: 150
A2: ענפי משנה | B2: ענף מרכז | H2: רכב חובה | I2: משאיות חובה | J2: רכב רכוש | K2: משאיות רכוש | L2: דירות | M2: בתי עסק
A3: חובה | B3: =H2 -> רכב חובה | D3: רכב חובה | G3: אחוז עמלות סוכנים | H3: 0.05 | I3: 0.05 | J3: 0.14 | K3: 0.11 | L3: 0.21 | M3: 0.18
A4: קסקו מקיף | B4: =J2 -> רכב רכוש | D4: רכב רכוש
A5: קסקו צד ג | B5: =J2 -> רכב רכוש | D5: רכב רכוש | H5: רכב חובה | I5: משאיות חובה | J5: רכב רכוש | K5: משאיות רכוש | L5: דירות | M5: בתי עסק
A6: חובה משאיות | B6: =I2 -> משאיות חובה | D6: משאיות חובה | G6: אחוז ביטוח משנה | H6: 0.135 | I6: 0.95 | J6: 0.8 | K6: 0.95 | L6: 0.85 | M6: 0.85
A7: חובה נגררים | B7: =I2 -> משאיות חובה | D7: משאיות חובה
A8: חובה אוטובוסים | B8: =I2 -> משאיות חובה | D8: משאיות חובה | G8: אחוז עמלת משנה | H8: 0.17222222 | I8: 0.15 | J8: 0.200875 | K8: 0.22 | L8: 0.24338235 | M8: 0.24338235
A9: קסקו משאיות | B9: =K2 -> משאיות רכוש | D9: משאיות רכוש
A10: קסקו נגררים | B10: =K2 -> משאיות רכוש | D10: משאיות רכוש | L10: 60 | M10: 70
A11: דירות | B11: =L2 -> דירות | D11: דירות
A12: צמה | B12: =K2 -> משאיות רכוש | D12: משאיות רכוש | H12: רכב חובה | I12: משאיות חובה | J12: רכב רכוש | K12: משאיות רכוש | L12: דירות | M12: בתי עסק
A13: בתי עסק | B13: =M2 -> בתי עסק | D13: בתי עסק | G13: אחוז LR | H13: 0.9 | I13: 0.9 | J13: 0.7 | K13: 0.7 | L13: 0.6 | M13: 0.7
E15: שנת | F15: 2025 | G15: 200000 | H15: 30000 | I15: 0.25
E16: שנת | F16: 2026 | G16: תחזית הנהלה וכלליות | H16: 42228 | I16: 0.25 | J16: חלוקה לרבעונים 25% | L16: חלוקה לענפים לפי יחס פרמיה
B18: לתאריך UPR | F18: 2025 | G18: הוצאות לשנת 2025 | H18: =IF(H33=F18,H15,0) -> 0
B19: 45747 | F19: 2026 | G19: הוצאות לשנת 2026 | H19: =IF(H33=F19,H16,0) -> 42228
B20: 45838 | N20: חלוקת הוצאות | P20: 2026 | Q20: 2025
B21: 45930 | N21: 1 | O21: רכישה ושיווק | P21: =$H$19*N21 -> 42228 | Q21: 20000
B22: 46022 | G22: פרמיון XOL הערה | H22: =K27*4 -> 3464 | I22: לשנה | J22: 0.25 | K22: לרבעון | N22: 0.3 | O22: תביעות | P22: =$H$19*N22 -> 12668.4
B23: 46112 | G23: חלוקה | N23: 0.2 | O23: אחר | P23: =$H$19*N23 -> 8445.6
B24: 46203 | G24: חובה פרטי | H24: =K24/K27 -> 0.86836028 | K24: 752 | P24: =SUM(P21:P23) -> 63342
B25: 46295 | G25: חובה משאיות | H25: =K25/K27 -> 0.073903002 | K25: 64
B26: 46387 | G26: דירות | H26: =K25/K27 -> 0.073903002 | K26: 50
K27: =K24+K25+K26 -> 866 | L27: 6000
B28: חודש יחוס - חודש UPR
B29: שנה | C29: 2026 | G29: הערכת החנסות מהשקעות
B30: רבעון | C30: 4 | G30: תשואה לשה | H30: 0.04 | I30: חלוקה בהתאם לפרמיה בשייר
B31: תאריך | C31: =DATE(C29,C33,C34) -> 46387 | H31: =H30/4 -> 0.01 | I31: לרבעון
B33: חודש | C33: {=_xlfn.SWITCH(C30, 1, 3, 2, 6,3,9,4,12)} -> 12 | G33: שנה | H33: 2026
B34: יום סוף חודש | C34: {=_xlfn.SWITCH(C30, 2, 30, 3, 30, 31)} -> 31 | G34: רבעון | H34: 4 | J34: כותרת הדוח | L34: דוח עסקי ביטוח | N34: שנת
G35: כותרות הדוח | H35: =VLOOKUP(H34,G37:H40,2) -> מצטבר ליום 31 בדצמבר
G36: רבעון | H36: כותר\ת | N36: =L34&" "&H35&" "&N34&" "&H33 -> דוח עסקי ביטוח מצטבר ליום 31 בדצמבר שנת 2026
G37: 1 | H37: מצטבר ליום 31 במרץ
G38: 2 | H38: מצטבר ליום 30 ביוני
G39: 3 | H39: מצטבר ליום 30 בספטמבר
G40: 4 | H40: מצטבר ליום 31 בדצמבר
F43: שנת | G43: רבעון | H43: הוצאות
F44: 2025 | G44: 1 | H44: #VALUE!
F45: 2025 | G45: 2
...

Sheet info
A1: שנה | B1: ענף משנה | C1: עמלות סוכנים | D1: ביטוח משנה | E1: עמלה משנה | F1: אחוז LR | H1: חלק קרנית בחובה | I1: 0.794
A2: 2025 | B2: חובה | C2: 0.05 | D2: 0.135 | E2: 0.1722 | F2: 0.9
A3: 2025 | B3: קסקו מקיף | C3: 0.14 | D3: 0.8 | E3: 0.2 | F3: 0.7
A4: 2025 | B4: קסקו צד ג | C4: 0.14 | D4: 0.8 | E4: 0.2 | F4: 0.7
A5: 2025 | B5: חובה משאיות | C5: 0.05 | D5: 0.95 | E5: 0.15 | F5: 0.9
A6: 2025 | B6: חובה נגררים | C6: 0.05 | D6: 0.95 | E6: 0.15 | F6: 0.9
A7: 2025 | B7: חובה אוטובוסים | C7: 0.05 | D7: 0.95 | E7: 0.15 | F7: 0.9
A8: 2025 | B8: קסקו משאיות | C8: 0.11 | D8: 0.95 | E8: 0.22 | F8: 0.7
A9: 2025 | B9: קסקו נגררים | C9: 0.11 | D9: 0.95 | E9: 0.22 | F9: 0.7
A10: 2025 | B10: צמה | C10: 0.11 | D10: 0.95 | E10: 0.22 | F10: 0.7
A11: 2025 | B11: דירות | C11: 0.21 | D11: 0.85 | E11: 0.2434 | F11: 0.8
A12: 2025 | B12: בתי עסק | C12: 0.18 | D12: 0.85 | E12: 0.2434 | F12: 0.7
A13: 2026 | B13: חובה | C13: 0.05 | D13: 0.135 | E13: 0.1722 | F13: 0.9
... A23: 2026 | B23: בתי עסק | C23: 0.18 | D23: 0.85 | E23: 0.2434 | F23: 0.7
A24: חלק קרנית בחובה
A25: 2025 | B25: רכב חובה | C25: 0.794
A26: 2026 | B26: משאיות חובה | C26: 0.794
A27: 2026 | B27: רכב חובה | C27: 0.794
A28: 2026 | B28: משאיות חובה | C28: 0.794

Sheet prod
A1: startDade | B1: מרכז | C1: ענף | D1: amount | F1: amount
A2: 45717 | B2: רכב חובה | C2: חובה | D2: 46319 | E2: =D2*1000 -> 46319000 | F2: =ROUND(E2,0) -> 46319000
A3: 45748 | B3: רכב חובה | C3: חובה | D3: 448737 | E3: =D3*1000 -> 448737000 | F3: =ROUND(E3,0) -> 448737000
A4: 45778 | B4: רכב חובה | C4: חובה | D4: 565905 | E4: =D4*1000 -> 565905000 | F4: =ROUND(E4,0) -> 565905000
A5: 45809 | B5: רכב חובה | C5: חובה | D5: 1426814 | E5: =D5*1000 -> 1426814000 | F5: =ROUND(E5,0) -> 1426814000
A6: 45839 | B6: רכב חובה | C6: חובה | D6: 2492297 | E6: =D6*1000 -> 2492297000 | F6: =ROUND(E6,0) -> 2492297000
A7: 45870 | B7: רכב חובה | C7: חובה | D7: 3093156 | E7: =D7*1000 -> 3093156000 | F7: =ROUND(E7,0) -> 3093156000
A8: 45901 | B8: רכב חובה | C8: חובה | D8: 5066358 | E8: =D8*1000 -> 5066358000 | F8: =ROUND(E8,0) -> 5066358000
A9: 45931 | B9: רכב חובה | C9: חובה | D9: 5169409 | E9: =D9*1000 -> 5169409000 | F9: =ROUND(E9,0) -> 5169409000
A10: 45962 | B10: רכב חובה | C10: חובה | D10: 5963173 | E10: =D10*1000 -> 5963173000 | F10: =ROUND(E10,0) -> 5963173000
A11: 45992 | B11: רכב חובה | C11: חובה | D11: 5782596 | E11: =D11*1000 -> 5782596000 | F11: =ROUND(E11,0) -> 5782596000
A12: 46023 | B12: רכב חובה | C12: חובה | D12: 5320000 | E12: =D12*1000 -> 5320000000 | F12: =ROUND(E12,0) -> 5320000000
A13: 46054 | B13: רכב חובה | C13: חובה | D13: 5130000 | E13: =D13*1000 -> 5130000000 | F13: =ROUND(E13,0) -> 5130000000
... A169: 46357 | B169: בתי עסק | C169: בתי עסק | D169: 565675 | E169: =D169*1000 -> 565675000 | F169: =ROUND(E169,0) -> 565675000
D170: 476342567 | E170: =SUM(E2:E169) -> 476342557000 | F170: =ROUND(E170,0) -> 476342557000
B203: {=VLOOKUP(info!#REF!,anaf,2,FALSE)} -> #REF!
A210: 402

Sheet data
A1: נתוני בסיס | I1: פרמטרים לחישוב | M1: נתונים לתחזית | S1: חישוב UPR | AC1: יתרת ימי ביטוח עתודה
M2: =SUM(M5:M100) -> 3.8025881e+08
H3: פרמיה בפרודוקציה | M3: פרמיה ללא קרנית
A4: year | B4: חודש | C4: quarterly | D4: =prod!A1 -> startDade | E4: endDate | F4: =prod!B1 -> מרכז | G4: =prod!C1 -> ענף | H4: =prod!D1 -> amount | I4: עמלות סוכנים | J4: ביטוח משנה | K4: עמלה משנה | L4: אחוז LR | M4: פרמיה ברוטו | N4: פרמיה משנה | O4: עמלה ברוטו | P4: עמלה משנה | Q4: תביעות ברוטו | R4: תביעות משנה | S4: 45747 | T4: 45838 | U4: 45930 | V4: 46022 | W4: 46112 | X4: 46203 | Y4: 46295 | Z4: 46387 | AC4: 45747 | AD4: 45777 | AE4: 45808 | AF4: 45838 | AG4: 45869 | AH4: 45900 | AI4: 45930 | AJ4: 45961 | AK4: 45991 | AL4: 46022 | AM4: 46053 | AN4: 46081 | AO4: 46112 | AP4: 46142 | AQ4: 46173 | AR4: 46203 | AS4: 46234 | AT4: 46265 | AU4: 46295 | AV4: 46326 | AW4: 46356 | AX4: 46387 | AY4: 45747 | AZ4: 45777 | BA4: 45808 | BB4: 45838 | BC4: 45869 | BD4: 45900 | BE4: 45930 | BF4: 45961 | BG4: 45992 | BH4: 46022 | BI4: 46053 | BJ4: 46081 | BK4: 46112 | BL4: 46142 | BM4: 46173 | BN4: 46203 | BO4: 46234 | BP4: 46265 | BQ4: 46295 | BR4: 46326 | BS4: 46356 | BT4: 46387
A5: =YEAR(D5) -> 2025 | B5: =MONTH(D5) -> 3 | C5: =IF(MONTH(D5)<=3,1,IF(MONTH(D5)<=6,2,IF(MONTH(D5)<=9,3,4))) -> 1 | D5: =prod!A2 -> 45717 | E5: =EDATE(D5,12)-1 -> 46081 | F5: =prod!B2 -> רכב חובה | G5: =prod!C2 -> חובה | H5: =prod!D2 -> 46319 | I5: =SUMIFS(info!C:C,info!$A:$A,data!$A5,info!$B:$B,data!$G5) -> 0.05 | J5: =SUMIFS(info!D:D,info!$A:$A,data!$A5,info!$B:$B,data!$G5) -> 0.135 | K5: =SUMIFS(info!E:E,info!$A:$A,data!$A5,info!$B:$B,data!$G5) -> 0.1722 | L5: =SUMIFS(info!F:F,info!$A:$A,data!$A5,info!$B:$B,data!$G5) -> 0.9 | M5: =IF(SUMIFS(info!$C$25:$C$27,info!$A$25:$A$27,data!A5,info!$B$25:$B$27,data!F5)<=0,1,SUMIFS(info!$C$25:$C$27,info!$A$25:$A$27,data!A5,info!$B$25:$B$27,data!F5))*H5 -> 36777.286 | N5: =H5*J5 -> 6253.065 | O5: =H5*I5 -> 2315.95 | P5: =N5*K5 -> 1076.7778 | Q5: =H5*L5 -> 41687.1 | R5: =Q5*J5 -> 5627.7585 | S5: =IF($D5>S$4,0,$M5*MAX(0,$E5-S$4)/($E5-$D5+1)) -> 33653.736 | T5: =IF($D5>T$4,0,$M5*MAX(0,$E5-T$4)/($E5-$D5+1)) -> 24484.604 | U5: =IF($D5>U$4,0,$M5*MAX(0,$E5-U$4)/($E5-$D5+1)) -> 15214.713 | V5: =IF($D5>V$4,0,$M5*MAX(0,$E5-V$4)/($E5-$D5+1)) -> 5944.8216 | W5: =IF($D5>W$4,0,$M5*MAX(0,$E5-W$4)/($E5-$D5+1)) -> 0 | X5: =IF($D5>X$4,0,$M5*MAX(0,$E5-X$4)/($E5-$D5+1)) -> 0 | Y5: =IF($D5>Y$4,0,$M5*MAX(0,$E5-Y$4)/($E5-$D5+1)) -> 0 | Z5: =IF($D5>Z$4,0,$M5*MAX(0,$E5-Z$4)/($E5-$D5+1)) -> 0 | AC5: =IF(($E5-AC$4)>365,0,($E5-AC$4)) -> 334 | AD5: =IF(($E5-AD$4)>365,0,($E5-AD$4)) -> 304 | AE5: =IF(($E5-AE$4)>365,0,($E5-AE$4)) -> 273 | AF5: =IF(($E5-AF$4)>365,0,($E5-AF$4)) -> 243 | AG5: =IF(($E5-AG$4)>365,0,($E5-AG$4)) -> 212 | AH5: =IF(($E5-AH$4)>365,0,($E5-AH$4)) -> 181 | AI5: =IF(($E5-AI$4)>365,0,($E5-AI$4)) -> 151 | AJ5: =IF(($E5-AJ$4)>365,0,($E5-AJ$4)) -> 120 | ... AX5: =IF(($E5-AX$4)>365,0,($E5-AX$4)) -> -306 | AY5: =IF(AC5<0,0,AC5) -> 334 | AZ5: =IF(AD5<0,0,AD5) -> 304 | BA5: =IF(AE5<0,0,AE5) -> 273 | BB5: =IF(AF5<0,0,AF5) -> 243 | BC5: =IF(AG5<0,0,AG5) -> 212 | BD5: =IF(AH5<0,0,AH5) -> 181 | BE5: =IF(AI5<0,0,AI5) -> 151 | BF5: =IF(AJ5<0,0,AJ5) -> 120 | ... BT5: =IF(AX5<0,0,AX5) -> 0
A6: =YEAR(D6) -> 2025 | B6: =MONTH(D6) -> 4 | C6: =IF(MONTH(D6)<=3,1,IF(MONTH(D6)<=6,2,IF(MONTH(D6)<=9,3,4))) -> 2 | D6: =prod!A3 -> 45748 | E6: =EDATE(D6,12)-1 -> 46112 | F6: =prod!B3 -> רכב חובה | G6: =prod!C3 -> חובה | H6: =prod!D3 -> 448737 | I6: =SUMIFS(info!C:C,info!$A:$A,data!$A6,info!$B:$B,data!$G6) -> 0.05 | J6: =SUMIFS(info!D:D,info!$A:$A,data!$A6,info!$B:$B,data!$G6) -> 0.135 | K6: =SUMIFS(info!E:E,info!$A:$A,data!$A6,info!$B:$B,data!$G6) -> 0.1722 | L6: =SUMIFS(info!F:F,info!$A:$A,data!$A6,info!$B:$B,data!$G6) -> 0.9 | M6: =IF(SUMIFS(info!$C$25:$C$27,info!$A$25:$A$27,data!A6,info!$B$25:$B$27,data!F6)<=0,1,SUMIFS(info!$C$25:$C$27,info!$A$25:$A$27,data!A6,info!$B$25:$B$27,data!F6))*H6 -> 356297.18 | N6: =H6*J6 -> 60579.495 | O6: =H6*I6 -> 22436.85 | P6: =N6*K6 -> 10431.789 | Q6: =H6*L6 -> 403863.3 | R6: =Q6*J6 -> 54521.546 | S6: =IF($D6>S$4,0,$M6*MAX(0,$E6-S$4)/($E6-$D6+1)) -> 0 | T6: =IF($D6>T$4,0,$M6*MAX(0,$E6-T$4)/($E6-$D6+1)) -> 267466.92 | U6: =IF($D6>U$4,0,$M6*MAX(0,$E6-U$4)/($E6-$D6+1)) -> 177660.51 | V6: =IF($D6>V$4,0,$M6*MAX(0,$E6-V$4)/($E6-$D6+1)) -> 87854.099 | W6: =IF($D6>W$4,0,$M6*MAX(0,$E6-W$4)/($E6-$D6+1)) -> 0 | X6: =IF($D6>X$4,0,$M6*MAX(0,$E6-X$4)/($E6-$D6+1)) -> 0 | Y6: =IF($D6>Y$4,0,$M6*MAX(0,$E6-Y$4)/($E6-$D6+1)) -> 0 | Z6: =IF($D6>Z$4,0,$M6*MAX(0,$E6-Z$4)/($E6-$D6+1)) -> 0 | AC6: =IF(($E6-AC$4)>365,0,($E6-AC$4)) -> 365 | AD6: =IF(($E6-AD$4)>365,0,($E6-AD$4)) -> 335 | AE6: =IF(($E6-AE$4)>365,0,($E6-AE$4)) -> 304 | AF6: =IF(($E6-AF$4)>365,0,($E6-AF$4)) -> 274 | AG6: =IF(($E6-AG$4)>365,0,($E6-AG$4)) -> 243 | AH6: =IF(($E6-AH$4)>365,0,($E6-AH$4)) -> 212 | AI6: =IF(($E6-AI$4)>365,0,($E6-AI$4)) -> 182 | AJ6: =IF(($E6-AJ$4)>365,0,($E6-AJ$4)) -> 151 | ... AX6: =IF(($E6-AX$4)>365,0,($E6-AX$4)) -> -275 | AY6: =IF(AC6<0,0,AC6) -> 365 | AZ6: =IF(AD6<0,0,AD6) -> 335 | BA6: =IF(AE6<0,0,AE6) -> 304 | BB6: =IF(AF6<0,0,AF6) -> 274 | BC6: =IF(AG6<0,0,AG6) -> 243 | BD6: =IF(AH6<0,0,AH6) -> 212 | BE6: =IF(AI6<0,0,AI6) -> 182 | BF6: =IF(AJ6<0,0,AJ6) -> 151 | ... BT6: =IF(AX6<0,0,AX6) -> 0
A7: =YEAR(D7) -> 2025 | B7: =MONTH(D7) -> 5 | C7: =IF(MONTH(D7)<=3,1,IF(MONTH(D7)<=6,2,IF(MONTH(D7)<=9,3,4))) -> 2 | D7: =prod!A4 -> 45778 | E7: =EDATE(D7,12)-1 -> 46142 | F7: =prod!B4 -> רכב חובה | G7: =prod!C4 -> חובה | H7: =prod!D4 -> 565905 | I7: =SUMIFS(info!C:C,info!$A:$A,data!$A7,info!$B:$B,data!$G7) -> 0.05 | J7: =SUMIFS(info!D:D,info!$A:$A,data!$A7,info!$B:$B,data!$G7) -> 0.135 | K7: =SUMIFS(info!E:E,info!$A:$A,data!$A7,info!$B:$B,data!$G7) -> 0.1722 | L7: =SUMIFS(info!F:F,info!$A:$A,data!$A7,info!$B:$B,data!$G7) -> 0.9 | M7: =IF(SUMIFS(info!$C$25:$C$27,info!$A$25:$A$27,data!A7,info!$B$25:$B$27,data!F7)<=0,1,SUMIFS(info!$C$25:$C$27,info!$A$25:$A$27,data!A7,info!$B$25:$B$27,data!F7))*H7 -> 449328.57 | N7: =H7*J7 -> 76397.175 | O7: =H7*I7 -> 28295.25 | P7: =N7*K7 -> 13155.594 | Q7: =H7*L7 -> 509314.5 | R7: =Q7*J7 -> 68757.458 | S7: =IF($D7>S$4,0,$M7*MAX(0,$E7-S$4)/($E7-$D7+1)) -> 0 | T7: =IF($D7>T$4,0,$M7*MAX(0,$E7-T$4)/($E7-$D7+1)) -> 374235.3 | U7: =IF($D7>U$4,0,$M7*MAX(0,$E7-U$4)/($E7-$D7+1)) -> 260979.88 | V7: =IF($D7>V$4,0,$M7*MAX(0,$E7-V$4)/($E7-$D7+1)) -> 147724.46 | W7: =IF($D7>W$4,0,$M7*MAX(0,$E7-W$4)/($E7-$D7+1)) -> 36931.115 | X7: =IF($D7>X$4,0,$M7*MAX(0,$E7-X$4)/($E7-$D7+1)) -> 0 | Y7: =IF($D7>Y$4,0,$M7*MAX(0,$E7-Y$4)/($E7-$D7+1)) -> 0 | Z7: =IF($D7>Z$4,0,$M7*MAX(0,$E7-Z$4)/($E7-$D7+1)) -> 0 | AC7: =IF(($E7-AC$4)>365,0,($E7-AC$4)) -> 0 | AD7: =IF(($E7-AD$4)>365,0,($E7-AD$4)) -> 365 | AE7: =IF(($E7-AE$4)>365,0,($E7-AE$4)) -> 334 | AF7: =IF(($E7-AF$4)>365,0,($E7-AF$4)) -> 304 | AG7: =IF(($E7-AG$4)>365,0,($E7-AG$4)) -> 273 | AH7: =IF(($E7-AH$4)>365,0,($E7-AH$4)) -> 242 | AI7: =IF(($E7-AI$4)>365,0,($E7-AI$4)) -> 212 | AJ7: =IF(($E7-AJ$4)>365,0,($E7-AJ$4)) -> 181 | ... AX7: =IF(($E7-AX$4)>365,0,($E7-AX$4)) -> -245 | AY7: =IF(AC7<0,0,AC7) -> 0 | AZ7: =IF(AD7<0,0,AD7) -> 365 | BA7: =IF(AE7<0,0,AE7) -> 334 | BB7: =IF(AF7<0,0,AF7) -> 304 | BC7: =IF(AG7<0,0,AG7) -> 273 | BD7: =IF(AH7<0,0,AH7) -> 242 | BE7: =IF(AI7<0,0,AI7) -> 212 | BF7: =IF(AJ7<0,0,AJ7) -> 181 | ... BT7: =IF(AX7<0,0,AX7) -> 0
A8: =YEAR(D8) -> 2025 | B8: =MONTH(D8) -> 6 | C8: =IF(MONTH(D8)<=3,1,IF(MONTH(D8)<=6,2,IF(MONTH(D8)<=9,3,4))) -> 2 | D8: =prod!A5 -> 45809 | E8: =EDATE(D8,12)-1 -> 46173 | F8: =prod!B5 -> רכב חובה | G8: =prod!C5 -> חובה | H8: =prod!D5 -> 1426814 | I8: =SUMIFS(info!C:C,info!$A:$A,data!$A8,info!$B:$B,data!$G8) -> 0.05 | J8: =SUMIFS(info!D:D,info!$A:$A,data!$A8,info!$B:$B,data!$G8) -> 0.135 | K8: =SUMIFS(info!E:E,info!$A:$A,data!$A8,info!$B:$B,data!$G8) -> 0.1722 | L8: =SUMIFS(info!F:F,info!$A:$A,data!$A8,info!$B:$B,data!$G8) -> 0.9 | M8: =IF(SUMIFS(info!$C$25:$C$27,info!$A$25:$A$27,data!A8,info!$B$25:$B$27,data!F8)<=0,1,SUMIFS(info!$C$25:$C$27,info!$A$25:$A$27,data!A8,info!$B$25:$B$27,data!F8))*H8 -> 1132890.3 | N8: =H8*J8 -> 192619.89 | O8: =H8*I8 -> 71340.7 | P8: =N8*K8 -> 33169.145 | Q8: =H8*L8 -> 1284132.6 | R8: =Q8*J8 -> 173357.9 | S8: =IF($D8>S$4,0,$M8*MAX(0,$E8-S$4)/($E8-$D8+1)) -> 0 | T8: =IF($D8>T$4,0,$M8*MAX(0,$E8-T$4)/($E8-$D8+1)) -> 1039776 | U8: =IF($D8>U$4,0,$M8*MAX(0,$E8-U$4)/($E8-$D8+1)) -> 754225.61 | V8: =IF($D8>V$4,0,$M8*MAX(0,$E8-V$4)/($E8-$D8+1)) -> 468675.17 | W8: =IF($D8>W$4,0,$M8*MAX(0,$E8-W$4)/($E8-$D8+1)) -> 189332.35 | X8: =IF($D8>X$4,0,$M8*MAX(0,$E8-X$4)/($E8-$D8+1)) -> 0 | Y8: =IF($D8>Y$4,0,$M8*MAX(0,$E8-Y$4)/($E8-$D8+1)) -> 0 | Z8: =IF($D8>Z$4,0,$M8*MAX(0,$E8-Z$4)/($E8-$D8+1)) -> 0 | AC8: =IF(($E8-AC$4)>365,0,($E8-AC$4)) -> 0 | AD8: =IF(($E8-AD$4)>365,0,($E8-AD$4)) -> 0 | AE8: =IF(($E8-AE$4)>365,0,($E8-AE$4)) -> 365 | AF8: =IF(($E8-AF$4)>365,0,($E8-AF$4)) -> 335 | AG8: =IF(($E8-AG$4)>365,0,($E8-AG$4)) -> 304 | AH8: =IF(($E8-AH$4)>365,0,($E8-AH$4)) -> 273 | AI8: =IF(($E8-AI$4)>365,0,($E8-AI$4)) -> 243 | AJ8: =IF(($E8-AJ$4)>365,0,($E8-AJ$4)) -> 212 | ... AX8: =IF(($E8-AX$4)>365,0,($E8-AX$4)) -> -214 | AY8: =IF(AC8<0,0,AC8) -> 0 | AZ8: =IF(AD8<0,0,AD8) -> 0 | BA8: =IF(AE8<0,0,AE8) -> 365 | BB8: =IF(AF8<0,0,AF8) -> 335 | BC8: =IF(AG8<0,0,AG8) -> 304 | BD8: =IF(AH8<0,0,AH8) -> 273 | BE8: =IF(AI8<0,0,AI8) -> 243 | BF8: =IF(AJ8<0,0,AJ8) -> 212 | ... BT8: =IF(AX8<0,0,AX8) -> 0
A9: =YEAR(D9) -> 2025 | B9: =MONTH(D9) -> 7 | C9: =IF(MONTH(D9)<=3,1,IF(MONTH(D9)<=6,2,IF(MONTH(D9)<=9,3,4))) -> 3 | D9: =prod!A6 -> 45839 | E9: =EDATE(D9,12)-1 -> 46203 | F9: =prod!B6 -> רכב חובה | G9: =prod!C6 -> חובה | H9: =prod!D6 -> 2492297 | I9: =SUMIFS(info!C:C,info!$A:$A,data!$A9,info!$B:$B,data!$G9) -> 0.05 | J9: =SUMIFS(info!D:D,info!$A:$A,data!$A9,info!$B:$B,data!$G9) -> 0.135 | K9: =SUMIFS(info!E:E,info!$A:$A,data!$A9,info!$B:$B,data!$G9) -> 0.1722 | L9: =SUMIFS(info!F:F,info!$A:$A,data!$A9,info!$B:$B,data!$G9) -> 0.9 | M9: =IF(SUMIFS(info!$C$25:$C$27,info!$A$25:$A$27,data!A9,info!$B$25:$B$27,data!F9)<=0,1,SUMIFS(info!$C$25:$C$27,info!$A$25:$A$27,data!A9,info!$B$25:$B$27,data!F9))*H9 -> 1978883.8 | N9: =H9*J9 -> 336460.1 | O9: =H9*I9 -> 124614.85 | P9: =N9*K9 -> 57938.428 | Q9: =H9*L9 -> 2243067.3 | R9: =Q9*J9 -> 302814.09 | S9: =IF($D9>S$4,0,$M9*MAX(0,$E9-S$4)/($E9-$D9+1)) -> 0 | T9: =IF($D9>T$4,0,$M9*MAX(0,$E9-T$4)/($E9-$D9+1)) -> 0 | U9: =IF($D9>U$4,0,$M9*MAX(0,$E9-U$4)/($E9-$D9+1)) -> 1480096.7 | V9: =IF($D9>V$4,0,$M9*MAX(0,$E9-V$4)/($E9-$D9+1)) -> 981309.51 | W9: =IF($D9>W$4,0,$M9*MAX(0,$E9-W$4)/($E9-$D9+1)) -> 493365.55 | X9: =IF($D9>X$4,0,$M9*MAX(0,$E9-X$4)/($E9-$D9+1)) -> 0 | Y9: =IF($D9>Y$4,0,$M9*MAX(0,$E9-Y$4)/($E9-$D9+1)) -> 0 | Z9: =IF($D9>Z$4,0,$M9*MAX(0,$E9-Z$4)/($E9-$D9+1)) -> 0 | AC9: =IF(($E9-AC$4)>365,0,($E9-AC$4)) -> 0 | AD9: =IF(($E9-AD$4)>365,0,($E9-AD$4)) -> 0 | AE9: =IF(($E9-AE$4)>365,0,($E9-AE$4)) -> 0 | AF9: =IF(($E9-AF$4)>365,0,($E9-AF$4)) -> 365 | AG9: =IF(($E9-AG$4)>365,0,($E9-AG$4)) -> 334 | AH9: =IF(($E9-AH$4)>365,0,($E9-AH$4)) -> 303 | AI9: =IF(($E9-AI$4)>365,0,($E9-AI$4)) -> 273 | AJ9: =IF(($E9-AJ$4)>365,0,($E9-AJ$4)) -> 242 | ... AX9: =IF(($E9-AX$4)>365,0,($E9-AX$4)) -> -184 | AY9: =IF(AC9<0,0,AC9) -> 0 | AZ9: =IF(AD9<0,0,AD9) -> 0 | BA9: =IF(AE9<0,0,AE9) -> 0 | BB9: =IF(AF9<0,0,AF9) -> 365 | BC9: =IF(AG9<0,0,AG9) -> 334 | BD9: =IF(AH9<0,0,AH9) -> 303 | BE9: =IF(AI9<0,0,AI9) -> 273 | BF9: =IF(AJ9<0,0,AJ9) -> 242 | ... BT9: =IF(AX9<0,0,AX9) -> 0
A10: =YEAR(D10) -> 2025 | B10: =MONTH(D10) -> 8 | C10: =IF(MONTH(D10)<=3,1,IF(MONTH(D10)<=6,2,IF(MONTH(D10)<=9,3,4))) -> 3 | D10: =prod!A7 -> 45870 | E10: =EDATE(D10,12)-1 -> 46234 | F10: =prod!B7 -> רכב חובה | G10: =prod!C7 -> חובה | H10: =prod!D7 -> 3093156 | I10: =SUMIFS(info!C:C,info!$A:$A,data!$A10,info!$B:$B,data!$G10) -> 0.05 | J10: =SUMIFS(info!D:D,info!$A:$A,data!$A10,info!$B:$B,data!$G10) -> 0.135 | K10: =SUMIFS(info!E:E,info!$A:$A,data!$A10,info!$B:$B,data!$G10) -> 0.1722 | L10: =SUMIFS(info!F:F,info!$A:$A,data!$A10,info!$B:$B,data!$G10) -> 0.9 | M10: =IF(SUMIFS(info!$C$25:$C$27,info!$A$25:$A$27,data!A10,info!$B$25:$B$27,data!F10)<=0,1,SUMIFS(info!$C$25:$C$27,info!$A$25:$A$27,data!A10,info!$B$25:$B$27,data!F10))*H10 -> 2455965.9 | N10: =H10*J10 -> 417576.06 | O10: =H10*I10 -> 154657.8 | P10: =N10*K10 -> 71906.598 | Q10: =H10*L10 -> 2783840.4 | R10: =Q10*J10 -> 375818.45 | S10: =IF($D10>S$4,0,$M10*MAX(0,$E10-S$4)/($E10-$D10+1)) -> 0 | T10: =IF($D10>T$4,0,$M10*MAX(0,$E10-T$4)/($E10-$D10+1)) -> 0 | U10: =IF($D10>U$4,0,$M10*MAX(0,$E10-U$4)/($E10-$D10+1)) -> 2045516.8 | V10: =IF($D10>V$4,0,$M10*MAX(0,$E10-V$4)/($E10-$D10+1)) -> 1426478.8 | W10: =IF($D10>W$4,0,$M10*MAX(0,$E10-W$4)/($E10-$D10+1)) -> 820898.18 | X10: =IF($D10>X$4,0,$M10*MAX(0,$E10-X$4)/($E10-$D10+1)) -> 208588.88 | Y10: =IF($D10>Y$4,0,$M10*MAX(0,$E10-Y$4)/($E10-$D10+1)) -> 0 | Z10: =IF($D10>Z$4,0,$M10*MAX(0,$E10-Z$4)/($E10-$D10+1)) -> 0 | AC10: =IF(($E10-AC$4)>365,0,($E10-AC$4)) -> 0 | AD10: =IF(($E10-AD$4)>365,0,($E10-AD$4)) -> 0 | AE10: =IF(($E10-AE$4)>365,0,($E10-AE$4)) -> 0 | AF10: =IF(($E10-AF$4)>365,0,($E10-AF$4)) -> 0 | AG10: =IF(($E10-AG$4)>365,0,($E10-AG$4)) -> 365 | AH10: =IF(($E10-AH$4)>365,0,($E10-AH$4)) -> 334 | AI10: =IF(($E10-AI$4)>365,0,($E10-AI$4)) -> 304 | AJ10: =IF(($E10-AJ$4)>365,0,($E10-AJ$4)) -> 273 | ... AX10: =IF(($E10-AX$4)>365,0,($E10-AX$4)) -> -153 | AY10: =IF(AC10<0,0,AC10) -> 0 | AZ10: =IF(AD10<0,0,AD10) -> 0 | BA10: =IF(AE10<0,0,AE10) -> 0 | BB10: =IF(AF10<0,0,AF10) -> 0 | BC10: =IF(AG10<0,0,AG10) -> 365 | BD10: =IF(AH10<0,0,AH10) -> 334 | BE10: =IF(AI10<0,0,AI10) -> 304 | BF10: =IF(AJ10<0,0,AJ10) -> 273 | ... BT10: =IF(AX10<0,0,AX10) -> 0
A11: =YEAR(D11) -> 2025 | B11: =MONTH(D11) -> 9 | C11: =IF(MONTH(D11)<=3,1,IF(MONTH(D11)<=6,2,IF(MONTH(D11)<=9,3,4))) -> 3 | D11: =prod!A8 -> 45901 | E11: =EDATE(D11,12)-1 -> 46265 | F11: =prod!B8 -> רכב חובה | G11: =prod!C8 -> חובה | H11: =prod!D8 -> 5066358 | I11: =SUMIFS(info!C:C,info!$A:$A,data!$A11,info!$B:$B,data!$G11) -> 0.05 | J11: =SUMIFS(info!D:D,info!$A:$A,data!$A11,info!$B:$B,data!$G11) -> 0.135 | K11: =SUMIFS(info!E:E,info!$A:$A,data!$A11,info!$B:$B,data!$G11) -> 0.1722 | L11: =SUMIFS(info!F:F,info!$A:$A,data!$A11,info!$B:$B,data!$G11) -> 0.9 | M11: =IF(SUMIFS(info!$C$25:$C$27,info!$A$25:$A$27,data!A11,info!$B$25:$B$27,data!F11)<=0,1,SUMIFS(info!$C$25:$C$27,info!$A$25:$A$27,data!A11,info!$B$25:$B$27,data!F11))*H11 -> 4022688.3 | N11: =H11*J11 -> 683958.33 | O11: =H11*I11 -> 253317.9 | P11: =N11*K11 -> 117777.62 | Q11: =H11*L11 -> 4559722.2 | R11: =Q11*J11 -> 615562.5 | S11: =IF($D11>S$4,0,$M11*MAX(0,$E11-S$4)/($E11-$D11+1)) -> 0 | T11: =IF($D11>T$4,0,$M11*MAX(0,$E11-T$4)/($E11-$D11+1)) -> 0 | U11: =IF($D11>U$4,0,$M11*MAX(0,$E11-U$4)/($E11-$D11+1)) -> 3692056.3 | V11: =IF($D11>V$4,0,$M11*MAX(0,$E11-V$4)/($E11-$D11+1)) -> 2678118.5 | W11: =IF($D11>W$4,0,$M11*MAX(0,$E11-W$4)/($E11-$D11+1)) -> 1686222.7 | X11: =IF($D11>X$4,0,$M11*MAX(0,$E11-X$4)/($E11-$D11+1)) -> 683305.95 | Y11: =IF($D11>Y$4,0,$M11*MAX(0,$E11-Y$4)/($E11-$D11+1)) -> 0 | Z11: =IF($D11>Z$4,0,$M11*MAX(0,$E11-Z$4)/($E11-$D11+1)) -> 0 | AC11: =IF(($E11-AC$4)>365,0,($E11-AC$4)) -> 0 | AD11: =IF(($E11-AD$4)>365,0,($E11-AD$4)) -> 0 | AE11: =IF(($E11-AE$4)>365,0,($E11-AE$4)) -> 0 | AF11: =IF(($E11-AF$4)>365,0,($E11-AF$4)) -> 0 | AG11: =IF(($E11-AG$4)>365,0,($E11-AG$4)) -> 0 | AH11: =IF(($E11-AH$4)>365,0,($E11-AH$4)) -> 365 | AI11: =IF(($E11-AI$4)>365,0,($E11-AI$4)) -> 335 | AJ11: =IF(($E11-AJ$4)>365,0,($E11-AJ$4)) -> 304 | ... AX11: =IF(($E11-AX$4)>365,0,($E11-AX$4)) -> -122 | AY11: =IF(AC11<0,0,AC11) -> 0 | AZ11: =IF(AD11<0,0,AD11) -> 0 | BA11: =IF(AE11<0,0,AE11) -> 0 | BB11: =IF(AF11<0,0,AF11) -> 0 | BC11: =IF(AG11<0,0,AG11) -> 0 | BD11: =IF(AH11<0,0,AH11) -> 365 | BE11: =IF(AI11<0,0,AI11) -> 335 | BF11: =IF(AJ11<0,0,AJ11) -> 304 | ... BT11: =IF(AX11<0,0,AX11) -> 0
A12: =YEAR(D12) -> 2025 | B12: =MONTH(D12) -> 10 | C12: =IF(MONTH(D12)<=3,1,IF(MONTH(D12)<=6,2,IF(MONTH(D12)<=9,3,4))) -> 4 | D12: =prod!A9 -> 45931 | E12: =EDATE(D12,12)-1 -> 46295 | F12: =prod!B9 -> רכב חובה | G12: =prod!C9 -> חובה | H12: =prod!D9 -> 5169409 | I12: =SUMIFS(info!C:C,info!$A:$A,data!$A12,info!$B:$B,data!$G12) -> 0.05 | J12: =SUMIFS(info!D:D,info!$A:$A,data!$A12,info!$B:$B,data!$G12) -> 0.135 | K12: =SUMIFS(info!E:E,info!$A:$A,data!$A12,info!$B:$B,data!$G12) -> 0.1722 | L12: =SUMIFS(info!F:F,info!$A:$A,data!$A12,info!$B:$B,data!$G12) -> 0.9 | M12: =IF(SUMIFS(info!$C$25:$C$27,info!$A$25:$A$27,data!A12,info!$B$25:$B$27,data!F12)<=0,1,SUMIFS(info!$C$25:$C$27,info!$A$25:$A$27,data!A12,info!$B$25:$B$27,data!F12))*H12 -> 4104510.7 | N12: =H12*J12 -> 697870.22 | O12: =H12*I12 -> 258470.45 | P12: =N12*K12 -> 120173.25 | Q12: =H12*L12 -> 4652468.1 | R12: =Q12*J12 -> 628083.19 | S12: =IF($D12>S$4,0,$M12*MAX(0,$E12-S$4)/($E12-$D12+1)) -> 0 | T12: =IF($D12>T$4,0,$M12*MAX(0,$E12-T$4)/($E12-$D12+1)) -> 0 | U12: =IF($D12>U$4,0,$M12*MAX(0,$E12-U$4)/($E12-$D12+1)) -> 0 | V12: =IF($D12>V$4,0,$M12*MAX(0,$E12-V$4)/($E12-$D12+1)) -> 3069949.1 | W12: =IF($D12>W$4,0,$M12*MAX(0,$E12-W$4)/($E12-$D12+1)) -> 2057878 | X12: =IF($D12>X$4,0,$M12*MAX(0,$E12-X$4)/($E12-$D12+1)) -> 1034561.6 | Y12: =IF($D12>Y$4,0,$M12*MAX(0,$E12-Y$4)/($E12-$D12+1)) -> 0 | Z12: =IF($D12>Z$4,0,$M12*MAX(0,$E12-Z$4)/($E12-$D12+1)) -> 0 | AC12: =IF(($E12-AC$4)>365,0,($E12-AC$4)) -> 0 | AD12: =IF(($E12-AD$4)>365,0,($E12-AD$4)) -> 0 | AE12: =IF(($E12-AE$4)>365,0,($E12-AE$4)) -> 0 | AF12: =IF(($E12-AF$4)>365,0,($E12-AF$4)) -> 0 | AG12: =IF(($E12-AG$4)>365,0,($E12-AG$4)) -> 0 | AH12: =IF(($E12-AH$4)>365,0,($E12-AH$4)) -> 0 | AI12: =IF(($E12-AI$4)>365,0,($E12-AI$4)) -> 365 | AJ12: =IF(($E12-AJ$4)>365,0,($E12-AJ$4)) -> 334 | ... AX12: =IF(($E12-AX$4)>365,0,($E12-AX$4)) -> -92 | AY12: =IF(AC12<0,0,AC12) -> 0 | AZ12: =IF(AD12<0,0,AD12) -> 0 | BA12: =IF(AE12<0,0,AE12) -> 0 | BB12: =IF(AF12<0,0,AF12) -> 0 | BC12: =IF(AG12<0,0,AG12) -> 0 | BD12: =IF(AH12<0,0,AH12) -> 0 | BE12: =IF(AI12<0,0,AI12) -> 365 | BF12: =IF(AJ12<0,0,AJ12) -> 334 | ... BT12: =IF(AX12<0,0,AX12) -> 0
A13: =YEAR(D13) -> 2025 | B13: =MONTH(D13) -> 11 | C13: =IF(MONTH(D13)<=3,1,IF(MONTH(D13)<=6,2,IF(MONTH(D13)<=9,3,4))) -> 4 | D13: =prod!A10 -> 45962 | E13: =EDATE(D13,12)-1 -> 46326 | F13: =prod!B10 -> רכב חובה | G13: =prod!C10 -> חובה | H13: =prod!D10 -> 5963173 | I13: =SUMIFS(info!C:C,info!$A:$A,data!$A13,info!$B:$B,data!$G13) -> 0.05 | J13: =SUMIFS(info!D:D,info!$A:$A,data!$A13,info!$B:$B,data!$G13) -> 0.135 | K13: =SUMIFS(info!E:E,info!$A:$A,data!$A13,info!$B:$B,data!$G13) -> 0.1722 | L13: =SUMIFS(info!F:F,info!$A:$A,data!$A13,info!$B:$B,data!$G13) -> 0.9 | M13: =IF(SUMIFS(info!$C$25:$C$27,info!$A$25:$A$27,data!A13,info!$B$25:$B$27,data!F13)<=0,1,SUMIFS(info!$C$25:$C$27,info!$A$25:$A$27,data!A13,info!$B$25:$B$27,data!F13))*H13 -> 4734759.4 | N13: =H13*J13 -> 805028.36 | O13: =H13*I13 -> 298158.65 | P13: =N13*K13 -> 138625.88 | Q13: =H13*L13 -> 5366855.7 | R13: =Q13*J13 -> 724525.52 | S13: =IF($D13>S$4,0,$M13*MAX(0,$E13-S$4)/($E13-$D13+1)) -> 0 | T13: =IF($D13>T$4,0,$M13*MAX(0,$E13-T$4)/($E13-$D13+1)) -> 0 | U13: =IF($D13>U$4,0,$M13*MAX(0,$E13-U$4)/($E13-$D13+1)) -> 0 | V13: =IF($D13>V$4,0,$M13*MAX(0,$E13-V$4)/($E13-$D13+1)) -> 3943470.8 | W13: =IF($D13>W$4,0,$M13*MAX(0,$E13-W$4)/($E13-$D13+1)) -> 2775995.9 | X13: =IF($D13>X$4,0,$M13*MAX(0,$E13-X$4)/($E13-$D13+1)) -> 1595549 | Y13: =IF($D13>Y$4,0,$M13*MAX(0,$E13-Y$4)/($E13-$D13+1)) -> 402130.25 | Z13: =IF($D13>Z$4,0,$M13*MAX(0,$E13-Z$4)/($E13-$D13+1)) -> 0 | AC13: =IF(($E13-AC$4)>365,0,($E13-AC$4)) -> 0 | AD13: =IF(($E13-AD$4)>365,0,($E13-AD$4)) -> 0 | AE13: =IF(($E13-AE$4)>365,0,($E13-AE$4)) -> 0 | AF13: =IF(($E13-AF$4)>365,0,($E13-AF$4)) -> 0 | AG13: =IF(($E13-AG$4)>365,0,($E13-AG$4)) -> 0 | AH13: =IF(($E13-AH$4)>365,0,($E13-AH$4)) -> 0 | AI13: =IF(($E13-AI$4)>365,0,($E13-AI$4)) -> 0 | AJ13: =IF(($E13-AJ$4)>365,0,($E13-AJ$4)) -> 365 | ... AX13: =IF(($E13-AX$4)>365,0,($E13-AX$4)) -> -61 | AY13: =IF(AC13<0,0,AC13) -> 0 | AZ13: =IF(AD13<0,0,AD13) -> 0 | BA13: =IF(AE13<0,0,AE13) -> 0 | BB13: =IF(AF13<0,0,AF13) -> 0 | BC13: =IF(AG13<0,0,AG13) -> 0 | BD13: =IF(AH13<0,0,AH13) -> 0 | BE13: =IF(AI13<0,0,AI13) -> 0 | BF13: =IF(AJ13<0,0,AJ13) -> 365 | ... BT13: =IF(AX13<0,0,AX13) -> 0
A14: =YEAR(D14) -> 2025 | B14: =MONTH(D14) -> 12 | C14: =IF(MONTH(D14)<=3,1,IF(MONTH(D14)<=6,2,IF(MONTH(D14)<=9,3,4))) -> 4 | D14: =prod!A11 -> 45992 | E14: =EDATE(D14,12)-1 -> 46356 | F14: =prod!B11 -> רכב חובה | G14: =prod!C11 -> חובה | H14: =prod!D11 -> 5782596 | I14: =SUMIFS(info!C:C,info!$A:$A,data!$A14,info!$B:$B,data!$G14) -> 0.05 | J14: =SUMIFS(info!D:D,info!$A:$A,data!$A14,info!$B:$B,data!$G14) -> 0.135 | K14: =SUMIFS(info!E:E,info!$A:$A,data!$A14,info!$B:$B,data!$G14) -> 0.1722 | L14: =SUMIFS(info!F:F,info!$A:$A,data!$A14,info!$B:$B,data!$G14) -> 0.9 | M14: =IF(SUMIFS(info!$C$25:$C$27,info!$A$25:$A$27,data!A14,info!$B$25:$B$27,data!F14)<=0,1,SUMIFS(info!$C$25:$C$27,info!$A$25:$A$27,data!A14,info!$B$25:$B$27,data!F14))*H14 -> 4591381.2 | N14: =H14*J14 -> 780650.46 | O14: =H14*I14 -> 289129.8 | P14: =N14*K14 -> 134428.01 | Q14: =H14*L14 -> 5204336.4 | R14: =Q14*J14 -> 702585.41 | S14: =IF($D14>S$4,0,$M14*MAX(0,$E14-S$4)/($E14-$D14+1)) -> 0 | T14: =IF($D14>T$4,0,$M14*MAX(0,$E14-T$4)/($E14-$D14+1)) -> 0 | U14: =IF($D14>U$4,0,$M14*MAX(0,$E14-U$4)/($E14-$D14+1)) -> 0 | V14: =IF($D14>V$4,0,$M14*MAX(0,$E14-V$4)/($E14-$D14+1)) -> 4201428.3 | W14: =IF($D14>W$4,0,$M14*MAX(0,$E14-W$4)/($E14-$D14+1)) -> 3069306.9 | X14: =IF($D14>X$4,0,$M14*MAX(0,$E14-X$4)/($E14-$D14+1)) -> 1924606.4 | Y14: =IF($D14>Y$4,0,$M14*MAX(0,$E14-Y$4)/($E14-$D14+1)) -> 767326.73 | Z14: =IF($D14>Z$4,0,$M14*MAX(0,$E14-Z$4)/($E14-$D14+1)) -> 0 | AC14: =IF(($E14-AC$4)>365,0,($E14-AC$4)) -> 0 | AD14: =IF(($E14-AD$4)>365,0,($E14-AD$4)) -> 0 | AE14: =IF(($E14-AE$4)>365,0,($E14-AE$4)) -> 0 | AF14: =IF(($E14-AF$4)>365,0,($E14-AF$4)) -> 0 | AG14: =IF(($E14-AG$4)>365,0,($E14-AG$4)) -> 0 | AH14: =IF(($E14-AH$4)>365,0,($E14-AH$4)) -> 0 | AI14: =IF(($E14-AI$4)>365,0,($E14-AI$4)) -> 0 | AJ14: =IF(($E14-AJ$4)>365,0,($E14-AJ$4)) -> 0 | ... AX14: =IF(($E14-AX$4)>365,0,($E14-AX$4)) -> -31 | AY14: =IF(AC14<0,0,AC14) -> 0 | AZ14: =IF(AD14<0,0,AD14) -> 0 | BA14: =IF(AE14<0,0,AE14) -> 0 | BB14: =IF(AF14<0,0,AF14) -> 0 | BC14: =IF(AG14<0,0,AG14) -> 0 | BD14: =IF(AH14<0,0,AH14) -> 0 | BE14: =IF(AI14<0,0,AI14) -> 0 | BF14: =IF(AJ14<0,0,AJ14) -> 0 | ... BT14: =IF(AX14<0,0,AX14) -> 0
A15: =YEAR(D15) -> 2026 | B15: =MONTH(D15) -> 1 | C15: =IF(MONTH(D15)<=3,1,IF(MONTH(D15)<=6,2,IF(MONTH(D15)<=9,3,4))) -> 1 | D15: =prod!A12 -> 46023 | E15: =EDATE(D15,12)-1 -> 46387 | F15: =prod!B12 -> רכב חובה | G15: =prod!C12 -> חובה | H15: =prod!D12 -> 5320000 | I15: =SUMIFS(info!C:C,info!$A:$A,data!$A15,info!$B:$B,data!$G15) -> 0.05 | J15: =SUMIFS(info!D:D,info!$A:$A,data!$A15,info!$B:$B,data!$G15) -> 0.135 | K15: =SUMIFS(info!E:E,info!$A:$A,data!$A15,info!$B:$B,data!$G15) -> 0.1722 | L15: =SUMIFS(info!F:F,info!$A:$A,data!$A15,info!$B:$B,data!$G15) -> 0.9 | M15: =IF(SUMIFS(info!$C$25:$C$27,info!$A$25:$A$27,data!A15,info!$B$25:$B$27,data!F15)<=0,1,SUMIFS(info!$C$25:$C$27,info!$A$25:$A$27,data!A15,info!$B$25:$B$27,data!F15))*H15 -> 4224080 | N15: =H15*J15 -> 718200 | O15: =H15*I15 -> 266000 | P15: =N15*K15 -> 123674.04 | Q15: =H15*L15 -> 4788000 | R15: =Q15*J15 -> 646380 | S15: =IF($D15>S$4,0,$M15*MAX(0,$E15-S$4)/($E15-$D15+1)) -> 0 | T15: =IF($D15>T$4,0,$M15*MAX(0,$E15-T$4)/($E15-$D15+1)) -> 0 | U15: =IF($D15>U$4,0,$M15*MAX(0,$E15-U$4)/($E15-$D15+1)) -> 0 | V15: =IF($D15>V$4,0,$M15*MAX(0,$E15-V$4)/($E15-$D15+1)) -> 0 | W15: =IF($D15>W$4,0,$M15*MAX(0,$E15-W$4)/($E15-$D15+1)) -> 3182526 | X15: =IF($D15>X$4,0,$M15*MAX(0,$E15-X$4)/($E15-$D15+1)) -> 2129399.2 | Y15: =IF($D15>Y$4,0,$M15*MAX(0,$E15-Y$4)/($E15-$D15+1)) -> 1064699.6 | Z15: =IF($D15>Z$4,0,$M15*MAX(0,$E15-Z$4)/($E15-$D15+1)) -> 0 | AC15: =IF(($E15-AC$4)>365,0,($E15-AC$4)) -> 0 | AD15: =IF(($E15-AD$4)>365,0,($E15-AD$4)) -> 0 | AE15: =IF(($E15-AE$4)>365,0,($E15-AE$4)) -> 0 | AF15: =IF(($E15-AF$4)>365,0,($E15-AF$4)) -> 0 | AG15: =IF(($E15-AG$4)>365,0,($E15-AG$4)) -> 0 | AH15: =IF(($E15-AH$4)>365,0,($E15-AH$4)) -> 0 | AI15: =IF(($E15-AI$4)>365,0,($E15-AI$4)) -> 0 | AJ15: =IF(($E15-AJ$4)>365,0,($E15-AJ$4)) -> 0 | ... AX15: =IF(($E15-AX$4)>365,0,($E15-AX$4)) -> 0 | AY15: =IF(AC15<0,0,AC15) -> 0 | AZ15: =IF(AD15<0,0,AD15) -> 0 | BA15: =IF(AE15<0,0,AE15) -> 0 | BB15: =IF(AF15<0,0,AF15) -> 0 | BC15: =IF(AG15<0,0,AG15) -> 0 | BD15: =IF(AH15<0,0,AH15) -> 0 | BE15: =IF(AI15<0,0,AI15) -> 0 | BF15: =IF(AJ15<0,0,AJ15) -> 0 | ... BT15: =IF(AX15<0,0,AX15) -> 0
A16: =YEAR(D16) -> 2026 | B16: =MONTH(D16) -> 2 | C16: =IF(MONTH(D16)<=3,1,IF(MONTH(D16)<=6,2,IF(MONTH(D16)<=9,3,4))) -> 1 | D16: =prod!A13 -> 46054 | E16: =EDATE(D16,12)-1 -> 46418 | F16: =prod!B13 -> רכב חובה | G16: =prod!C13 -> חובה | H16: =prod!D13 -> 5130000 | I16: =SUMIFS(info!C:C,info!$A:$A,data!$A16,info!$B:$B,data!$G16) -> 0.05 | J16: =SUMIFS(info!D:D,info!$A:$A,data!$A16,info!$B:$B,data!$G16) -> 0.135 | K16: =SUMIFS(info!E:E,info!$A:$A,data!$A16,info!$B:$B,data!$G16) -> 0.1722 | L16: =SUMIFS(info!F:F,info!$A:$A,data!$A16,info!$B:$B,data!$G16) -> 0.9 | M16: =IF(SUMIFS(info!$C$25:$C$27,info!$A$25:$A$27,data!A16,info!$B$25:$B$27,data!F16)<=0,1,SUMIFS(info!$C$25:$C$27,info!$A$25:$A$27,data!A16,info!$B$25:$B$27,data!F16))*H16 -> 4073220 | N16: =H16*J16 -> 692550 | O16: =H16*I16 -> 256500 | P16: =N16*K16 -> 119257.11 | Q16: =H16*L16 -> 4617000 | R16: =Q16*J16 -> 623295 | S16: =IF($D16>S$4,0,$M16*MAX(0,$E16-S$4)/($E16-$D16+1)) -> 0 | T16: =IF($D16>T$4,0,$M16*MAX(0,$E16-T$4)/($E16-$D16+1)) -> 0 | U16: =IF($D16>U$4,0,$M16*MAX(0,$E16-U$4)/($E16-$D16+1)) -> 0 | V16: =IF($D16>V$4,0,$M16*MAX(0,$E16-V$4)/($E16-$D16+1)) -> 0 | W16: =IF($D16>W$4,0,$M16*MAX(0,$E16-W$4)/($E16-$D16+1)) -> 3414809.1 | X16: =IF($D16>X$4,0,$M16*MAX(0,$E16-X$4)/($E16-$D16+1)) -> 2399294 | Y16: =IF($D16>Y$4,0,$M16*MAX(0,$E16-Y$4)/($E16-$D16+1)) -> 1372619.3 | Z16: =IF($D16>Z$4,0,$M16*MAX(0,$E16-Z$4)/($E16-$D16+1)) -> 345944.71 | AC16: =IF(($E16-AC$4)>365,0,($E16-AC$4)) -> 0 | AD16: =IF(($E16-AD$4)>365,0,($E16-AD$4)) -> 0 | AE16: =IF(($E16-AE$4)>365,0,($E16-AE$4)) -> 0 | AF16: =IF(($E16-AF$4)>365,0,($E16-AF$4)) -> 0 | AG16: =IF(($E16-AG$4)>365,0,($E16-AG$4)) -> 0 | AH16: =IF(($E16-AH$4)>365,0,($E16-AH$4)) -> 0 | AI16: =IF(($E16-AI$4)>365,0,($E16-AI$4)) -> 0 | AJ16: =IF(($E16-AJ$4)>365,0,($E16-AJ$4)) -> 0 | ... AX16: =IF(($E16-AX$4)>365,0,($E16-AX$4)) -> 31 | AY16: =IF(AC16<0,0,AC16) -> 0 | AZ16: =IF(AD16<0,0,AD16) -> 0 | BA16: =IF(AE16<0,0,AE16) -> 0 | BB16: =IF(AF16<0,0,AF16) -> 0 | BC16: =IF(AG16<0,0,AG16) -> 0 | BD16: =IF(AH16<0,0,AH16) -> 0 | BE16: =IF(AI16<0,0,AI16) -> 0 | BF16: =IF(AJ16<0,0,AJ16) -> 0 | ... BT16: =IF(AX16<0,0,AX16) -> 31
... A130: =YEAR(D130) -> 2026 | B130: =MONTH(D130) -> 12 | C130: =IF(MONTH(D130)<=3,1,IF(MONTH(D130)<=6,2,IF(MONTH(D130)<=9,3,4))) -> 4 | D130: =prod!A127 -> 46357 | E130: =EDATE(D130,12)-1 -> 46721 | F130: =prod!B127 -> משאיות רכוש | G130: =prod!C127 -> קסקו נגררים | H130: =prod!D127 -> 347120 | I130: =SUMIFS(info!C:C,info!$A:$A,data!$A130,info!$B:$B,data!$G130) -> 0.11 | J130: =SUMIFS(info!D:D,info!$A:$A,data!$A130,info!$B:$B,data!$G130) -> 0.95 | K130: =SUMIFS(info!E:E,info!$A:$A,data!$A130,info!$B:$B,data!$G130) -> 0.22 | L130: =SUMIFS(info!F:F,info!$A:$A,data!$A130,info!$B:$B,data!$G130) -> 0.7 | M130: =IF(SUMIFS(info!$C$25:$C$27,info!$A$25:$A$27,data!A130,info!$B$25:$B$27,data!F130)<=0,1,SUMIFS(info!$C$25:$C$27,info!$A$25:$A$27,data!A130,info!$B$25:$B$27,data!F130))*H130 -> 347120 | N130: =H130*J130 -> 329764 | O130: =H130*I130 -> 38183.2 | P130: =N130*K130 -> 72548.08 | Q130: =H130*L130 -> 242984 | R130: =Q130*J130 -> 230834.8 | S130: =IF($D130>S$4,0,$M130*MAX(0,$E130-S$4)/($E130-$D130+1)) -> 0 | T130: =IF($D130>T$4,0,$M130*MAX(0,$E130-T$4)/($E130-$D130+1)) -> 0 | U130: =IF($D130>U$4,0,$M130*MAX(0,$E130-U$4)/($E130-$D130+1)) -> 0 | V130: =IF($D130>V$4,0,$M130*MAX(0,$E130-V$4)/($E130-$D130+1)) -> 0 | W130: =IF($D130>W$4,0,$M130*MAX(0,$E130-W$4)/($E130-$D130+1)) -> 0 | X130: =IF($D130>X$4,0,$M130*MAX(0,$E130-X$4)/($E130-$D130+1)) -> 0 | Y130: =IF($D130>Y$4,0,$M130*MAX(0,$E130-Y$4)/($E130-$D130+1)) -> 0 | Z130: =IF($D130>Z$4,0,$M130*MAX(0,$E130-Z$4)/($E130-$D130+1)) -> 317638.58 | AC130: =IF(($E130-AC$4)>365,0,($E130-AC$4)) -> 0 | AD130: =IF(($E130-AD$4)>365,0,($E130-AD$4)) -> 0 | AE130: =IF(($E130-AE$4)>365,0,($E130-AE$4)) -> 0 | AF130: =IF(($E130-AF$4)>365,0,($E130-AF$4)) -> 0 | AG130: =IF(($E130-AG$4)>365,0,($E130-AG$4)) -> 0 | AH130: =IF(($E130-AH$4)>365,0,($E130-AH$4)) -> 0 | AI130: =IF(($E130-AI$4)>365,0,($E130-AI$4)) -> 0 | AJ130: =IF(($E130-AJ$4)>365,0,($E130-AJ$4)) -> 0 | ... AX130: =IF(($E130-AX$4)>365,0,($E130-AX$4)) -> 334 | AY130: =IF(AC130<0,0,AC130) -> 0 | AZ130: =IF(AD130<0,0,AD130) -> 0 | BA130: =IF(AE130<0,0,AE130) -> 0 | BB130: =IF(AF130<0,0,AF130) -> 0 | BC130: =IF(AG130<0,0,AG130) -> 0 | BD130: =IF(AH130<0,0,AH130) -> 0 | BE130: =IF(AI130<0,0,AI130) -> 0 | BF130: =IF(AJ130<0,0,AJ130) -> 0 | ... BT130: =IF(AX130<0,0,AX130) -> 334
A131: =YEAR(D131) -> 2026 | B131: =MONTH(D131) -> 1 | C131: =IF(MONTH(D131)<=3,1,IF(MONTH(D131)<=6,2,IF(MONTH(D131)<=9,3,4))) -> 1 | D131: =prod!A128 -> 46023 | E131: =EDATE(D131,12)-1 -> 46387 | F131: =prod!B128 -> משאיות רכוש | G131: =prod!C128 -> צמה | H131: =prod!D128 -> 1440000 | I131: =SUMIFS(info!C:C,info!$A:$A,data!$A131,info!$B:$B,data!$G131) -> 0.11 | J131: =SUMIFS(info!D:D,info!$A:$A,data!$A131,info!$B:$B,data!$G131) -> 0.95 | K131: =SUMIFS(info!E:E,info!$A:$A,data!$A131,info!$B:$B,data!$G131) -> 0.22 | L131: =SUMIFS(info!F:F,info!$A:$A,data!$A131,info!$B:$B,data!$G131) -> 0.7 | M131: =IF(SUMIFS(info!$C$25:$C$27,info!$A$25:$A$27,data!A131,info!$B$25:$B$27,data!F131)<=0,1,SUMIFS(info!$C$25:$C$27,info!$A$25:$A$27,data!A131,info!$B$25:$B$27,data!F131))*H131 -> 1440000 | N131: =H131*J131 -> 1368000 | O131: =H131*I131 -> 158400 | P131: =N131*K131 -> 300960 | Q131: =H131*L131 -> 1008000 | R131: =Q131*J131 -> 957600 | S131: =IF($D131>S$4,0,$M131*MAX(0,$E131-S$4)/($E131-$D131+1)) -> 0 | T131: =IF($D131>T$4,0,$M131*MAX(0,$E131-T$4)/($E131-$D131+1)) -> 0 | U131: =IF($D131>U$4,0,$M131*MAX(0,$E131-U$4)/($E131-$D131+1)) -> 0 | V131: =IF($D131>V$4,0,$M131*MAX(0,$E131-V$4)/($E131-$D131+1)) -> 0 | W131: =IF($D131>W$4,0,$M131*MAX(0,$E131-W$4)/($E131-$D131+1)) -> 1084931.5 | X131: =IF($D131>X$4,0,$M131*MAX(0,$E131-X$4)/($E131-$D131+1)) -> 725917.81 | Y131: =IF($D131>Y$4,0,$M131*MAX(0,$E131-Y$4)/($E131-$D131+1)) -> 362958.9 | Z131: =IF($D131>Z$4,0,$M131*MAX(0,$E131-Z$4)/($E131-$D131+1)) -> 0 | AC131: =IF(($E131-AC$4)>365,0,($E131-AC$4)) -> 0 | AD131: =IF(($E131-AD$4)>365,0,($E131-AD$4)) -> 0 | AE131: =IF(($E131-AE$4)>365,0,($E131-AE$4)) -> 0 | AF131: =IF(($E131-AF$4)>365,0,($E131-AF$4)) -> 0 | AG131: =IF(($E131-AG$4)>365,0,($E131-AG$4)) -> 0 | AH131: =IF(($E131-AH$4)>365,0,($E131-AH$4)) -> 0 | AI131: =IF(($E131-AI$4)>365,0,($E131-AI$4)) -> 0 | AJ131: =IF(($E131-AJ$4)>365,0,($E131-AJ$4)) -> 0 | ... BT131: =IF(($E131-BT$4)>365,0,($E131-BT$4)) -> 0
A132: =YEAR(D132) -> 2026 | B132: =MONTH(D132) -> 2 | C132: =IF(MONTH(D132)<=3,1,IF(MONTH(D132)<=6,2,IF(MONTH(D132)<=9,3,4))) -> 1 | D132: =prod!A129 -> 46054 | E132: =EDATE(D132,12)-1 -> 46418 | F132: =prod!B129 -> משאיות רכוש | G132: =prod!C129 -> צמה | H132: =prod!D129 -> 523636 | I132: =SUMIFS(info!C:C,info!$A:$A,data!$A132,info!$B:$B,data!$G132) -> 0.11 | J132: =SUMIFS(info!D:D,info!$A:$A,data!$A132,info!$B:$B,data!$G132) -> 0.95 | K132: =SUMIFS(info!E:E,info!$A:$A,data!$A132,info!$B:$B,data!$G132) -> 0.22 | L132: =SUMIFS(info!F:F,info!$A:$A,data!$A132,info!$B:$B,data!$G132) -> 0.7 | M132: =IF(SUMIFS(info!$C$25:$C$27,info!$A$25:$A$27,data!A132,info!$B$25:$B$27,data!F132)<=0,1,SUMIFS(info!$C$25:$C$27,info!$A$25:$A$27,data!A132,info!$B$25:$B$27,data!F132))*H132 -> 523636 | N132: =H132*J132 -> 497454.2 | O132: =H132*I132 -> 57599.96 | P132: =N132*K132 -> 109439.92 | Q132: =H132*L132 -> 366545.2 | R132: =Q132*J132 -> 348217.94 | S132: =IF($D132>S$4,0,$M132*MAX(0,$E132-S$4)/($E132-$D132+1)) -> 0 | T132: =IF($D132>T$4,0,$M132*MAX(0,$E132-T$4)/($E132-$D132+1)) -> 0 | U132: =IF($D132>U$4,0,$M132*MAX(0,$E132-U$4)/($E132-$D132+1)) -> 0 | V132: =IF($D132>V$4,0,$M132*MAX(0,$E132-V$4)/($E132-$D132+1)) -> 0 | W132: =IF($D132>W$4,0,$M132*MAX(0,$E132-W$4)/($E132-$D132+1)) -> 438993.47 | X132: =IF($D132>X$4,0,$M132*MAX(0,$E132-X$4)/($E132-$D132+1)) -> 308443.12 | Y132: =IF($D132>Y$4,0,$M132*MAX(0,$E132-Y$4)/($E132-$D132+1)) -> 176458.16 | Z132: =IF($D132>Z$4,0,$M132*MAX(0,$E132-Z$4)/($E132-$D132+1)) -> 44473.195 | AC132: =IF(($E132-AC$4)>365,0,($E132-AC$4)) -> 0 | AD132: =IF(($E132-AD$4)>365,0,($E132-AD$4)) -> 0 | AE132: =IF(($E132-AE$4)>365,0,($E132-AE$4)) -> 0 | AF132: =IF(($E132-AF$4)>365,0,($E132-AF$4)) -> 0 | AG132: =IF(($E132-AG$4)>365,0,($E132-AG$4)) -> 0 | AH132: =IF(($E132-AH$4)>365,0,($E132-AH$4)) -> 0 | AI132: =IF(($E132-AI$4)>365,0,($E132-AI$4)) -> 0 | AJ132: =IF(($E132-AJ$4)>365,0,($E132-AJ$4)) -> 0 | ... BT132: =IF(($E132-BT$4)>365,0,($E132-BT$4)) -> 31
A133: =YEAR(D133) -> 2026 | B133: =MONTH(D133) -> 3 | C133: =IF(MONTH(D133)<=3,1,IF(MONTH(D133)<=6,2,IF(MONTH(D133)<=9,3,4))) -> 1 | D133: =prod!A130 -> 46082 | E133: =EDATE(D133,12)-1 -> 46446 | F133: =prod!B130 -> משאיות רכוש | G133: =prod!C130 -> צמה | H133: =prod!D130 -> 523636 | I133: =SUMIFS(info!C:C,info!$A:$A,data!$A133,info!$B:$B,data!$G133) -> 0.11 | J133: =SUMIFS(info!D:D,info!$A:$A,data!$A133,info!$B:$B,data!$G133) -> 0.95 | K133: =SUMIFS(info!E:E,info!$A:$A,data!$A133,info!$B:$B,data!$G133) -> 0.22 | L133: =SUMIFS(info!F:F,info!$A:$A,data!$A133,info!$B:$B,data!$G133) -> 0.7 | M133: =IF(SUMIFS(info!$C$25:$C$27,info!$A$25:$A$27,data!A133,info!$B$25:$B$27,data!F133)<=0,1,SUMIFS(info!$C$25:$C$27,info!$A$25:$A$27,data!A133,info!$B$25:$B$27,data!F133))*H133 -> 523636 | N133: =H133*J133 -> 497454.2 | O133: =H133*I133 -> 57599.96 | P133: =N133*K133 -> 109439.92 | Q133: =H133*L133 -> 366545.2 | R133: =Q133*J133 -> 348217.94 | S133: =IF($D133>S$4,0,$M133*MAX(0,$E133-S$4)/($E133-$D133+1)) -> 0 | T133: =IF($D133>T$4,0,$M133*MAX(0,$E133-T$4)/($E133-$D133+1)) -> 0 | U133: =IF($D133>U$4,0,$M133*MAX(0,$E133-U$4)/($E133-$D133+1)) -> 0 | V133: =IF($D133>V$4,0,$M133*MAX(0,$E133-V$4)/($E133-$D133+1)) -> 0 | W133: =IF($D133>W$4,0,$M133*MAX(0,$E133-W$4)/($E133-$D133+1)) -> 479162.81 | X133: =IF($D133>X$4,0,$M133*MAX(0,$E133-X$4)/($E133-$D133+1)) -> 348612.46 | Y133: =IF($D133>Y$4,0,$M133*MAX(0,$E133-Y$4)/($E133-$D133+1)) -> 216627.5 | Z133: =IF($D133>Z$4,0,$M133*MAX(0,$E133-Z$4)/($E133-$D133+1)) -> 84642.532 | AC133: =IF(($E133-AC$4)>365,0,($E133-AC$4)) -> 0 | AD133: =IF(($E133-AD$4)>365,0,($E133-AD$4)) -> 0 | AE133: =IF(($E133-AE$4)>365,0,($E133-AE$4)) -> 0 | AF133: =IF(($E133-AF$4)>365,0,($E133-AF$4)) -> 0 | AG133: =IF(($E133-AG$4)>365,0,($E133-AG$4)) -> 0 | AH133: =IF(($E133-AH$4)>365,0,($E133-AH$4)) -> 0 | AI133: =IF(($E133-AI$4)>365,0,($E133-AI$4)) -> 0 | AJ133: =IF(($E133-AJ$4)>365,0,($E133-AJ$4)) -> 0 | ... BT133: =IF(($E133-BT$4)>365,0,($E133-BT$4)) -> 59
A134: =YEAR(D134) -> 2026 | B134: =MONTH(D134) -> 4 | C134: =IF(MONTH(D134)<=3,1,IF(MONTH(D134)<=6,2,IF(MONTH(D134)<=9,3,4))) -> 2 | D134: =prod!A131 -> 46113 | E134: =EDATE(D134,12)-1 -> 46477 | F134: =prod!B131 -> משאיות רכוש | G134: =prod!C131 -> צמה | H134: =prod!D131 -> 523636 | I134: =SUMIFS(info!C:C,info!$A:$A,data!$A134,info!$B:$B,data!$G134) -> 0.11 | J134: =SUMIFS(info!D:D,info!$A:$A,data!$A134,info!$B:$B,data!$G134) -> 0.95 | K134: =SUMIFS(info!E:E,info!$A:$A,data!$A134,info!$B:$B,data!$G134) -> 0.22 | L134: =SUMIFS(info!F:F,info!$A:$A,data!$A134,info!$B:$B,data!$G134) -> 0.7 | M134: =IF(SUMIFS(info!$C$25:$C$27,info!$A$25:$A$27,data!A134,info!$B$25:$B$27,data!F134)<=0,1,SUMIFS(info!$C$25:$C$27,info!$A$25:$A$27,data!A134,info!$B$25:$B$27,data!F134))*H134 -> 523636 | N134: =H134*J134 -> 497454.2 | O134: =H134*I134 -> 57599.96 | P134: =N134*K134 -> 109439.92 | Q134: =H134*L134 -> 366545.2 | R134: =Q134*J134 -> 348217.94 | S134: =IF($D134>S$4,0,$M134*MAX(0,$E134-S$4)/($E134-$D134+1)) -> 0 | T134: =IF($D134>T$4,0,$M134*MAX(0,$E134-T$4)/($E134-$D134+1)) -> 0 | U134: =IF($D134>U$4,0,$M134*MAX(0,$E134-U$4)/($E134-$D134+1)) -> 0 | V134: =IF($D134>V$4,0,$M134*MAX(0,$E134-V$4)/($E134-$D134+1)) -> 0 | W134: =IF($D134>W$4,0,$M134*MAX(0,$E134-W$4)/($E134-$D134+1)) -> 0 | X134: =IF($D134>X$4,0,$M134*MAX(0,$E134-X$4)/($E134-$D134+1)) -> 393085.65 | Y134: =IF($D134>Y$4,0,$M134*MAX(0,$E134-Y$4)/($E134-$D134+1)) -> 261100.69 | Z134: =IF($D134>Z$4,0,$M134*MAX(0,$E134-Z$4)/($E134-$D134+1)) -> 129115.73 | AC134: =IF(($E134-AC$4)>365,0,($E134-AC$4)) -> 0 | AD134: =IF(($E134-AD$4)>365,0,($E134-AD$4)) -> 0 | AE134: =IF(($E134-AE$4)>365,0,($E134-AE$4)) -> 0 | AF134: =IF(($E134-AF$4)>365,0,($E134-AF$4)) -> 0 | AG134: =IF(($E134-AG$4)>365,0,($E134-AG$4)) -> 0 | AH134: =IF(($E134-AH$4)>365,0,($E134-AH$4)) -> 0 | AI134: =IF(($E134-AI$4)>365,0,($E134-AI$4)) -> 0 | AJ134: =IF(($E134-AJ$4)>365,0,($E134-AJ$4)) -> 0 | ... BT134: =IF(($E134-BT$4)>365,0,($E134-BT$4)) -> 90
A135: =YEAR(D135) -> 2026 | B135: =MONTH(D135) -> 5 | C135: =IF(MONTH(D135)<=3,1,IF(MONTH(D135)<=6,2,IF(MONTH(D135)<=9,3,4))) -> 2 | D135: =prod!A132 -> 46143 | E135: =EDATE(D135,12)-1 -> 46507 | F135: =prod!B132 -> משאיות רכוש | G135: =prod!C132 -> צמה | H135: =prod!D132 -> 523636 | I135: =SUMIFS(info!C:C,info!$A:$A,data!$A135,info!$B:$B,data!$G135) -> 0.11 | J135: =SUMIFS(info!D:D,info!$A:$A,data!$A135,info!$B:$B,data!$G135) -> 0.95 | K135: =SUMIFS(info!E:E,info!$A:$A,data!$A135,info!$B:$B,data!$G135) -> 0.22 | L135: =SUMIFS(info!F:F,info!$A:$A,data!$A135,info!$B:$B,data!$G135) -> 0.7 | M135: =IF(SUMIFS(info!$C$25:$C$27,info!$A$25:$A$27,data!A135,info!$B$25:$B$27,data!F135)<=0,1,SUMIFS(info!$C$25:$C$27,info!$A$25:$A$27,data!A135,info!$B$25:$B$27,data!F135))*H135 -> 523636 | N135: =H135*J135 -> 497454.2 | O135: =H135*I135 -> 57599.96 | P135: =N135*K135 -> 109439.92 | Q135: =H135*L135 -> 366545.2 | R135: =Q135*J135 -> 348217.94 | S135: =IF($D135>S$4,0,$M135*MAX(0,$E135-S$4)/($E135-$D135+1)) -> 0 | T135: =IF($D135>T$4,0,$M135*MAX(0,$E135-T$4)/($E135-$D135+1)) -> 0 | U135: =IF($D135>U$4,0,$M135*MAX(0,$E135-U$4)/($E135-$D135+1)) -> 0 | V135: =IF($D135>V$4,0,$M135*MAX(0,$E135-V$4)/($E135-$D135+1)) -> 0 | W135: =IF($D135>W$4,0,$M135*MAX(0,$E135-W$4)/($E135-$D135+1)) -> 0 | X135: =IF($D135>X$4,0,$M135*MAX(0,$E135-X$4)/($E135-$D135+1)) -> 436124.23 | Y135: =IF($D135>Y$4,0,$M135*MAX(0,$E135-Y$4)/($E135-$D135+1)) -> 304139.27 | Z135: =IF($D135>Z$4,0,$M135*MAX(0,$E135-Z$4)/($E135-$D135+1)) -> 172154.3 | AC135: =IF(($E135-AC$4)>365,0,($E135-AC$4)) -> 0 | AD135: =IF(($E135-AD$4)>365,0,($E135-AD$4)) -> 0 | AE135: =IF(($E135-AE$4)>365,0,($E135-AE$4)) -> 0 | AF135: =IF(($E135-AF$4)>365,0,($E135-AF$4)) -> 0 | AG135: =IF(($E135-AG$4)>365,0,($E135-AG$4)) -> 0 | AH135: =IF(($E135-AH$4)>365,0,($E135-AH$4)) -> 0 | AI135: =IF(($E135-AI$4)>365,0,($E135-AI$4)) -> 0 | AJ135: =IF(($E135-AJ$4)>365,0,($E135-AJ$4)) -> 0 | ... BT135: =IF(($E135-BT$4)>365,0,($E135-BT$4)) -> 120
A136: =YEAR(D136) -> 2026 | B136: =MONTH(D136) -> 6 | C136: =IF(MONTH(D136)<=3,1,IF(MONTH(D136)<=6,2,IF(MONTH(D136)<=9,3,4))) -> 2 | D136: =prod!A133 -> 46174 | E136: =EDATE(D136,12)-1 -> 46538 | F136: =prod!B133 -> משאיות רכוש | G136: =prod!C133 -> צמה | H136: =prod!D133 -> 523636 | I136: =SUMIFS(info!C:C,info!$A:$A,data!$A136,info!$B:$B,data!$G136) -> 0.11 | J136: =SUMIFS(info!D:D,info!$A:$A,data!$A136,info!$B:$B,data!$G136) -> 0.95 | K136: =SUMIFS(info!E:E,info!$A:$A,data!$A136,info!$B:$B,data!$G136) -> 0.22 | L136: =SUMIFS(info!F:F,info!$A:$A,data!$A136,info!$B:$B,data!$G136) -> 0.7 | M136: =IF(SUMIFS(info!$C$25:$C$27,info!$A$25:$A$27,data!A136,info!$B$25:$B$27,data!F136)<=0,1,SUMIFS(info!$C$25:$C$27,info!$A$25:$A$27,data!A136,info!$B$25:$B$27,data!F136))*H136 -> 523636 | N136: =H136*J136 -> 497454.2 | O136: =H136*I136 -> 57599.96 | P136: =N136*K136 -> 109439.92 | Q136: =H136*L136 -> 366545.2 | R136: =Q136*J136 -> 348217.94 | S136: =IF($D136>S$4,0,$M136*MAX(0,$E136-S$4)/($E136-$D136+1)) -> 0 | T136: =IF($D136>T$4,0,$M136*MAX(0,$E136-T$4)/($E136-$D136+1)) -> 0 | U136: =IF($D136>U$4,0,$M136*MAX(0,$E136-U$4)/($E136-$D136+1)) -> 0 | V136: =IF($D136>V$4,0,$M136*MAX(0,$E136-V$4)/($E136-$D136+1)) -> 0 | W136: =IF($D136>W$4,0,$M136*MAX(0,$E136-W$4)/($E136-$D136+1)) -> 0 | X136: =IF($D136>X$4,0,$M136*MAX(0,$E136-X$4)/($E136-$D136+1)) -> 480597.42 | Y136: =IF($D136>Y$4,0,$M136*MAX(0,$E136-Y$4)/($E136-$D136+1)) -> 348612.46 | Z136: =IF($D136>Z$4,0,$M136*MAX(0,$E136-Z$4)/($E136-$D136+1)) -> 216627.5 | AC136: =IF(($E136-AC$4)>365,0,($E136-AC$4)) -> 0 | AD136: =IF(($E136-AD$4)>365,0,($E136-AD$4)) -> 0 | AE136: =IF(($E136-AE$4)>365,0,($E136-AE$4)) -> 0 | AF136: =IF(($E136-AF$4)>365,0,($E136-AF$4)) -> 0 | AG136: =IF(($E136-AG$4)>365,0,($E136-AG$4)) -> 0 | AH136: =IF(($E136-AH$4)>365,0,($E136-AH$4)) -> 0 | AI136: =IF(($E136-AI$4)>365,0,($E136-AI$4)) -> 0 | AJ136: =IF(($E136-AJ$4)>365,0,($E136-AJ$4)) -> 0 | ... BT136: =IF(($E136-BT$4)>365,0,($E136-BT$4)) -> 151
A137: =YEAR(D137) -> 2026 | B137: =MONTH(D137) -> 7 | C137: =IF(MONTH(D137)<=3,1,IF(MONTH(D137)<=6,2,IF(MONTH(D137)<=9,3,4))) -> 3 | D137: =prod!A134 -> 46204 | E137: =EDATE(D137,12)-1 -> 46568 | F137: =prod!B134 -> משאיות רכוש | G137: =prod!C134 -> צמה | H137: =prod!D134 -> 523636 | I137: =SUMIFS(info!C:C,info!$A:$A,data!$A137,info!$B:$B,data!$G137) -> 0.11 | J137: =SUMIFS(info!D:D,info!$A:$A,data!$A137,info!$B:$B,data!$G137) -> 0.95 | K137: =SUMIFS(info!E:E,info!$A:$A,data!$A137,info!$B:$B,data!$G137) -> 0.22 | L137: =SUMIFS(info!F:F,info!$A:$A,data!$A137,info!$B:$B,data!$G137) -> 0.7 | M137: =IF(SUMIFS(info!$C$25:$C$27,info!$A$25:$A$27,data!A137,info!$B$25:$B$27,data!F137)<=0,1,SUMIFS(info!$C$25:$C$27,info!$A$25:$A$27,data!A137,info!$B$25:$B$27,data!F137))*H137 -> 523636 | N137: =H137*J137 -> 497454.2 | O137: =H137*I137 -> 57599.96 | P137: =N137*K137 -> 109439.92 | Q137: =H137*L137 -> 366545.2 | R137: =Q137*J137 -> 348217.94 | S137: =IF($D137>S$4,0,$M137*MAX(0,$E137-S$4)/($E137-$D137+1)) -> 0 | T137: =IF($D137>T$4,0,$M137*MAX(0,$E137-T$4)/($E137-$D137+1)) -> 0 | U137: =IF($D137>U$4,0,$M137*MAX(0,$E137-U$4)/($E137-$D137+1)) -> 0 | V137: =IF($D137>V$4,0,$M137*MAX(0,$E137-V$4)/($E137-$D137+1)) -> 0 | W137: =IF($D137>W$4,0,$M137*MAX(0,$E137-W$4)/($E137-$D137+1)) -> 0 | X137: =IF($D137>X$4,0,$M137*MAX(0,$E137-X$4)/($E137-$D137+1)) -> 0 | Y137: =IF($D137>Y$4,0,$M137*MAX(0,$E137-Y$4)/($E137-$D137+1)) -> 391651.04 | Z137: =IF($D137>Z$4,0,$M137*MAX(0,$E137-Z$4)/($E137-$D137+1)) -> 259666.07 | AC137: =IF(($E137-AC$4)>365,0,($E137-AC$4)) -> 0 | AD137: =IF(($E137-AD$4)>365,0,($E137-AD$4)) -> 0 | AE137: =IF(($E137-AE$4)>365,0,($E137-AE$4)) -> 0 | AF137: =IF(($E137-AF$4)>365,0,($E137-AF$4)) -> 0 | AG137: =IF(($E137-AG$4)>365,0,($E137-AG$4)) -> 0 | AH137: =IF(($E137-AH$4)>365,0,($E137-AH$4)) -> 0 | AI137: =IF(($E137-AI$4)>365,0,($E137-AI$4)) -> 0 | AJ137: =IF(($E137-AJ$4)>365,0,($E137-AJ$4)) -> 0 | ... BT137: =IF(($E137-BT$4)>365,0,($E137-BT$4)) -> 181
A138: =YEAR(D138) -> 2026 | B138: =MONTH(D138) -> 8 | C138: =IF(MONTH(D138)<=3,1,IF(MONTH(D138)<=6,2,IF(MONTH(D138)<=9,3,4))) -> 3 | D138: =prod!A135 -> 46235 | E138: =EDATE(D138,12)-1 -> 46599 | F138: =prod!B135 -> משאיות רכוש | G138: =prod!C135 -> צמה | H138: =prod!D135 -> 523636 | I138: =SUMIFS(info!C:C,info!$A:$A,data!$A138,info!$B:$B,data!$G138) -> 0.11 | J138: =SUMIFS(info!D:D,info!$A:$A,data!$A138,info!$B:$B,data!$G138) -> 0.95 | K138: =SUMIFS(info!E:E,info!$A:$A,data!$A138,info!$B:$B,data!$G138) -> 0.22 | L138: =SUMIFS(info!F:F,info!$A:$A,data!$A138,info!$B:$B,data!$G138) -> 0.7 | M138: =IF(SUMIFS(info!$C$25:$C$27,info!$A$25:$A$27,data!A138,info!$B$25:$B$27,data!F138)<=0,1,SUMIFS(info!$C$25:$C$27,info!$A$25:$A$27,data!A138,info!$B$25:$B$27,data!F138))*H138 -> 523636 | N138: =H138*J138 -> 497454.2 | O138: =H138*I138 -> 57599.96 | P138: =N138*K138 -> 109439.92 | Q138: =H138*L138 -> 366545.2 | R138: =Q138*J138 -> 348217.94 | S138: =IF($D138>S$4,0,$M138*MAX(0,$E138-S$4)/($E138-$D138+1)) -> 0 | T138: =IF($D138>T$4,0,$M138*MAX(0,$E138-T$4)/($E138-$D138+1)) -> 0 | U138: =IF($D138>U$4,0,$M138*MAX(0,$E138-U$4)/($E138-$D138+1)) -> 0 | V138: =IF($D138>V$4,0,$M138*MAX(0,$E138-V$4)/($E138-$D138+1)) -> 0 | W138: =IF($D138>W$4,0,$M138*MAX(0,$E138-W$4)/($E138-$D138+1)) -> 0 | X138: =IF($D138>X$4,0,$M138*MAX(0,$E138-X$4)/($E138-$D138+1)) -> 0 | Y138: =IF($D138>Y$4,0,$M138*MAX(0,$E138-Y$4)/($E138-$D138+1)) -> 436124.23 | Z138: =IF($D138>Z$4,0,$M138*MAX(0,$E138-Z$4)/($E138-$D138+1)) -> 304139.27 | AC138: =IF(($E138-AC$4)>365,0,($E138-AC$4)) -> 0 | AD138: =IF(($E138-AD$4)>365,0,($E138-AD$4)) -> 0 | AE138: =IF(($E138-AE$4)>365,0,($E138-AE$4)) -> 0 | AF138: =IF(($E138-AF$4)>365,0,($E138-AF$4)) -> 0 | AG138: =IF(($E138-AG$4)>365,0,($E138-AG$4)) -> 0 | AH138: =IF(($E138-AH$4)>365,0,($E138-AH$4)) -> 0 | AI138: =IF(($E138-AI$4)>365,0,($E138-AI$4)) -> 0 | AJ138: =IF(($E138-AJ$4)>365,0,($E138-AJ$4)) -> 0 | ... BT138: =IF(($E138-BT$4)>365,0,($E138-BT$4)) -> 212
A139: =YEAR(D139) -> 2026 | B139: =MONTH(D139) -> 9 | C139: =IF(MONTH(D139)<=3,1,IF(MONTH(D139)<=6,2,IF(MONTH(D139)<=9,3,4))) -> 3 | D139: =prod!A136 -> 46266 | E139: =EDATE(D139,12)-1 -> 46630 | F139: =prod!B136 -> משאיות רכוש | G139: =prod!C136 -> צמה | H139: =prod!D136 -> 523636 | I139: =SUMIFS(info!C:C,info!$A:$A,data!$A139,info!$B:$B,data!$G139) -> 0.11 | J139: =SUMIFS(info!D:D,info!$A:$A,data!$A139,info!$B:$B,data!$G139) -> 0.95 | K139: =SUMIFS(info!E:E,info!$A:$A,data!$A139,info!$B:$B,data!$G139) -> 0.22 | L139: =SUMIFS(info!F:F,info!$A:$A,data!$A139,info!$B:$B,data!$G139) -> 0.7 | M139: =IF(SUMIFS(info!$C$25:$C$27,info!$A$25:$A$27,data!A139,info!$B$25:$B$27,data!F139)<=0,1,SUMIFS(info!$C$25:$C$27,info!$A$25:$A$27,data!A139,info!$B$25:$B$27,data!F139))*H139 -> 523636 | N139: =H139*J139 -> 497454.2 | O139: =H139*I139 -> 57599.96 | P139: =N139*K139 -> 109439.92 | Q139: =H139*L139 -> 366545.2 | R139: =Q139*J139 -> 348217.94 | S139: =IF($D139>S$4,0,$M139*MAX(0,$E139-S$4)/($E139-$D139+1)) -> 0 | T139: =IF($D139>T$4,0,$M139*MAX(0,$E139-T$4)/($E139-$D139+1)) -> 0 | U139: =IF($D139>U$4,0,$M139*MAX(0,$E139-U$4)/($E139-$D139+1)) -> 0 | V139: =IF($D139>V$4,0,$M139*MAX(0,$E139-V$4)/($E139-$D139+1)) -> 0 | W139: =IF($D139>W$4,0,$M139*MAX(0,$E139-W$4)/($E139-$D139+1)) -> 0 | X139: =IF($D139>X$4,0,$M139*MAX(0,$E139-X$4)/($E139-$D139+1)) -> 0 | Y139: =IF($D139>Y$4,0,$M139*MAX(0,$E139-Y$4)/($E139-$D139+1)) -> 480597.42 | Z139: =IF($D139>Z$4,0,$M139*MAX(0,$E139-Z$4)/($E139-$D139+1)) -> 348612.46 | AC139: =IF(($E139-AC$4)>365,0,($E139-AC$4)) -> 0 | AD139: =IF(($E139-AD$4)>365,0,($E139-AD$4)) -> 0 | AE139: =IF(($E139-AE$4)>365,0,($E139-AE$4)) -> 0 | AF139: =IF(($E139-AF$4)>365,0,($E139-AF$4)) -> 0 | AG139: =IF(($E139-AG$4)>365,0,($E139-AG$4)) -> 0 | AH139: =IF(($E139-AH$4)>365,0,($E139-AH$4)) -> 0 | AI139: =IF(($E139-AI$4)>365,0,($E139-AI$4)) -> 0 | AJ139: =IF(($E139-AJ$4)>365,0,($E139-AJ$4)) -> 0 | ... BT139: =IF(($E139-BT$4)>365,0,($E139-BT$4)) -> 243
A140: =YEAR(D140) -> 2026 | B140: =MONTH(D140) -> 10 | C140: =IF(MONTH(D140)<=3,1,IF(MONTH(D140)<=6,2,IF(MONTH(D140)<=9,3,4))) -> 4 | D140: =prod!A137 -> 46296 | E140: =EDATE(D140,12)-1 -> 46660 | F140: =prod!B137 -> משאיות רכוש | G140: =prod!C137 -> צמה | H140: =prod!D137 -> 523636 | I140: =SUMIFS(info!C:C,info!$A:$A,data!$A140,info!$B:$B,data!$G140) -> 0.11 | J140: =SUMIFS(info!D:D,info!$A:$A,data!$A140,info!$B:$B,data!$G140) -> 0.95 | K140: =SUMIFS(info!E:E,info!$A:$A,data!$A140,info!$B:$B,data!$G140) -> 0.22 | L140: =SUMIFS(info!F:F,info!$A:$A,data!$A140,info!$B:$B,data!$G140) -> 0.7 | M140: =IF(SUMIFS(info!$C$25:$C$27,info!$A$25:$A$27,data!A140,info!$B$25:$B$27,data!F140)<=0,1,SUMIFS(info!$C$25:$C$27,info!$A$25:$A$27,data!A140,info!$B$25:$B$27,data!F140))*H140 -> 523636 | N140: =H140*J140 -> 497454.2 | O140: =H140*I140 -> 57599.96 | P140: =N140*K140 -> 109439.92 | Q140: =H140*L140 -> 366545.2 | R140: =Q140*J140 -> 348217.94 | S140: =IF($D140>S$4,0,$M140*MAX(0,$E140-S$4)/($E140-$D140+1)) -> 0 | T140: =IF($D140>T$4,0,$M140*MAX(0,$E140-T$4)/($E140-$D140+1)) -> 0 | U140: =IF($D140>U$4,0,$M140*MAX(0,$E140-U$4)/($E140-$D140+1)) -> 0 | V140: =IF($D140>V$4,0,$M140*MAX(0,$E140-V$4)/($E140-$D140+1)) -> 0 | W140: =IF($D140>W$4,0,$M140*MAX(0,$E140-W$4)/($E140-$D140+1)) -> 0 | X140: =IF($D140>X$4,0,$M140*MAX(0,$E140-X$4)/($E140-$D140+1)) -> 0 | Y140: =IF($D140>Y$4,0,$M140*MAX(0,$E140-Y$4)/($E140-$D140+1)) -> 0 | Z140: =IF($D140>Z$4,0,$M140*MAX(0,$E140-Z$4)/($E140-$D140+1)) -> 391651.04 | AC140: =IF(($E140-AC$4)>365,0,($E140-AC$4)) -> 0 | AD140: =IF(($E140-AD$4)>365,0,($E140-AD$4)) -> 0 | AE140: =IF(($E140-AE$4)>365,0,($E140-AE$4)) -> 0 | AF140: =IF(($E140-AF$4)>365,0,($E140-AF$4)) -> 0 | AG140: =IF(($E140-AG$4)>365,0,($E140-AG$4)) -> 0 | AH140: =IF(($E140-AH$4)>365,0,($E140-AH$4)) -> 0 | AI140: =IF(($E140-AI$4)>365,0,($E140-AI$4)) -> 0 | AJ140: =IF(($E140-AJ$4)>365,0,($E140-AJ$4)) -> 0 | ... BT140: =IF(($E140-BT$4)>365,0,($E140-BT$4)) -> 273
A141: =YEAR(D141) -> 2026 | B141: =MONTH(D141) -> 11 | C141: =IF(MONTH(D141)<=3,1,IF(MONTH(D141)<=6,2,IF(MONTH(D141)<=9,3,4))) -> 4 | D141: =prod!A138 -> 46327 | E141: =EDATE(D141,12)-1 -> 46691 | F141: =prod!B138 -> משאיות רכוש | G141: =prod!C138 -> צמה | H141: =prod!D138 -> 523636 | I141: =SUMIFS(info!C:C,info!$A:$A,data!$A141,info!$B:$B,data!$G141) -> 0.11 | J141: =SUMIFS(info!D:D,info!$A:$A,data!$A141,info!$B:$B,data!$G141) -> 0.95 | K141: =SUMIFS(info!E:E,info!$A:$A,data!$A141,info!$B:$B,data!$G141) -> 0.22 | L141: =SUMIFS(info!F:F,info!$A:$A,data!$A141,info!$B:$B,data!$G141) -> 0.7 | M141: =IF(SUMIFS(info!$C$25:$C$27,info!$A$25:$A$27,data!A141,info!$B$25:$B$27,data!F141)<=0,1,SUMIFS(info!$C$25:$C$27,info!$A$25:$A$27,data!A141,info!$B$25:$B$27,data!F141))*H141 -> 523636 | N141: =H141*J141 -> 497454.2 | O141: =H141*I141 -> 57599.96 | P141: =N141*K141 -> 109439.92 | Q141: =H141*L141 -> 366545.2 | R141: =Q141*J141 -> 348217.94 | S141: =IF($D141>S$4,0,$M141*MAX(0,$E141-S$4)/($E141-$D141+1)) -> 0 | T141: =IF($D141>T$4,0,$M141*MAX(0,$E141-T$4)/($E141-$D141+1)) -> 0 | U141: =IF($D141>U$4,0,$M141*MAX(0,$E141-U$4)/($E141-$D141+1)) -> 0 | V141: =IF($D141>V$4,0,$M141*MAX(0,$E141-V$4)/($E141-$D141+1)) -> 0 | W141: =IF($D141>W$4,0,$M141*MAX(0,$E141-W$4)/($E141-$D141+1)) -> 0 | X141: =IF($D141>X$4,0,$M141*MAX(0,$E141-X$4)/($E141-$D141+1)) -> 0 | Y141: =IF($D141>Y$4,0,$M141*MAX(0,$E141-Y$4)/($E141-$D141+1)) -> 0 | Z141: =IF($D141>Z$4,0,$M141*MAX(0,$E141-Z$4)/($E141-$D141+1)) -> 436124.23 | AC141: =IF(($E141-AC$4)>365,0,($E141-AC$4)) -> 0 | AD141: =IF(($E141-AD$4)>365,0,($E141-AD$4)) -> 0 | AE141: =IF(($E141-AE$4)>365,0,($E141-AE$4)) -> 0 | AF141: =IF(($E141-AF$4)>365,0,($E141-AF$4)) -> 0 | AG141: =IF(($E141-AG$4)>365,0,($E141-AG$4)) -> 0 | AH141: =IF(($E141-AH$4)>365,0,($E141-AH$4)) -> 0 | AI141: =IF(($E141-AI$4)>365,0,($E141-AI$4)) -> 0 | AJ141: =IF(($E141-AJ$4)>365,0,($E141-AJ$4)) -> 0 | ... BT141: =IF(($E141-BT$4)>365,0,($E141-BT$4)) -> 304
A142: =YEAR(D142) -> 2026 | B142: =MONTH(D142) -> 12 | C142: =IF(MONTH(D142)<=3,1,IF(MONTH(D142)<=6,2,IF(MONTH(D142)<=9,3,4))) -> 4 | D142: =prod!A139 -> 46357 | E142: =EDATE(D142,12)-1 -> 46721 | F142: =prod!B139 -> משאיות רכוש | G142: =prod!C139 -> צמה | H142: =prod!D139 -> 523636 | I142: =SUMIFS(info!C:C,info!$A:$A,data!$A142,info!$B:$B,data!$G142) -> 0.11 | J142: =SUMIFS(info!D:D,info!$A:$A,data!$A142,info!$B:$B,data!$G142) -> 0.95 | K142: =SUMIFS(info!E:E,info!$A:$A,data!$A142,info!$B:$B,data!$G142) -> 0.22 | L142: =SUMIFS(info!F:F,info!$A:$A,data!$A142,info!$B:$B,data!$G142) -> 0.7 | M142: =IF(SUMIFS(info!$C$25:$C$27,info!$A$25:$A$27,data!A142,info!$B$25:$B$27,data!F142)<=0,1,SUMIFS(info!$C$25:$C$27,info!$A$25:$A$27,data!A142,info!$B$25:$B$27,data!F142))*H142 -> 523636 | N142: =H142*J142 -> 497454.2 | O142: =H142*I142 -> 57599.96 | P142: =N142*K142 -> 109439.92 | Q142: =H142*L142 -> 366545.2 | R142: =Q142*J142 -> 348217.94 | S142: =IF($D142>S$4,0,$M142*MAX(0,$E142-S$4)/($E142-$D142+1)) -> 0 | T142: =IF($D142>T$4,0,$M142*MAX(0,$E142-T$4)/($E142-$D142+1)) -> 0 | U142: =IF($D142>U$4,0,$M142*MAX(0,$E142-U$4)/($E142-$D142+1)) -> 0 | V142: =IF($D142>V$4,0,$M142*MAX(0,$E142-V$4)/($E142-$D142+1)) -> 0 | W142: =IF($D142>W$4,0,$M142*MAX(0,$E142-W$4)/($E142-$D142+1)) -> 0 | X142: =IF($D142>X$4,0,$M142*MAX(0,$E142-X$4)/($E142-$D142+1)) -> 0 | Y142: =IF($D142>Y$4,0,$M142*MAX(0,$E142-Y$4)/($E142-$D142+1)) -> 0 | Z142: =IF($D142>Z$4,0,$M142*MAX(0,$E142-Z$4)/($E142-$D142+1)) -> 479162.81 | AC142: =IF(($E142-AC$4)>365,0,($E142-AC$4)) -> 0 | AD142: =IF(($E142-AD$4)>365,0,($E142-AD$4)) -> 0 | AE142: =IF(($E142-AE$4)>365,0,($E142-AE$4)) -> 0 | AF142: =IF(($E142-AF$4)>365,0,($E142-AF$4)) -> 0 | AG142: =IF(($E142-AG$4)>365,0,($E142-AG$4)) -> 0 | AH142: =IF(($E142-AH$4)>365,0,($E142-AH$4)) -> 0 | AI142: =IF(($E142-AI$4)>365,0,($E142-AI$4)) -> 0 | AJ142: =IF(($E142-AJ$4)>365,0,($E142-AJ$4)) -> 0 | ... BT142: =IF(($E142-BT$4)>365,0,($E142-BT$4)) -> 334
